Workbook

Sheet 项目描述
B5: 工程名称： | C5: 泰国INTEQC T2 | F5: 联系地址： | L5: 联系方法：
B7: 电气设计人员： | C7: 魏正彪 | E7: 联系方法： | H7: 开始时间： | K7: 结束时间：
B8: 工艺设计 | E8: 联系方法： | H8: 业务员 | K8: 联系方法：
B9: 程序设计人员： | E9: 联系方法： | H9: 开始时间： | K9: 结束时间：
B10: 现场调试人员1： | E10: 联系方法： | H10: 开始时间： | K10: 结束时间：
B11: 现场调试人员2： | E11: 联系方法： | H11: 开始时间： | K11: 结束时间：
B14: 工程描述：【设计负责人填写】
B15: 全电脑控制方式
B18: 1513 CPU+ET200SP
B19: 1510单机共用
B25: IO修改备注
A26: 1
A27: 2
A28: 3
A29: 4
A30: 5
A31: 6
A32: 7
A33: 8
A34: 9
A35: 10
A36: 11
A37: 12
A38: 13

Sheet MCC1-2
B1: 序号 | C1: 地址 | D1: 符号表 | E1: 设备编号 | F1: 设备名称 | G1: 信号名称 | H1: 备注
B2: 1 | C2: PIW200 | D2: =RI1-AI1 | E2: R0101 | F2: 提升机 | G2: 电流检测 | H2: 4-20MA
B3: 2 | C3: PIW202 | D3: =RI1-AI1 | E3: R0206 | F3: 提升机 | G3: 电流检测 | H3: 4-20MA
B4: 3 | C4: PIW204 | D4: =RI1-AI1 | E4: G0104_3 | F4: 粉碎机 | G4: 电流检测 | H4: 4-20MA
B5: 4 | C5: PIW206 | D5: =RI1-AI1 | E5: G0108 | F5: 粉碎风机 | G5: 电流检测 | H5: 4-20MA
B6: 1 | C6: PIW208 | D6: =RI1-AI2 | E6: G0103T1 | F6: 喂料器 | G6: 测温 | H6: 4-20MA
B7: 2 | C7: PIW210 | D7: =RI1-AI2 | E7: G0104T1 | F7: 粉碎机 | G7: 测温1 | H7: 4-20MA
B8: 3 | C8: PIW212 | D8: =RI1-AI2 | E8: G0104T2 | F8: 粉碎机 | G8: 测温2 | H8: 4-20MA
B9: 4 | C9: PIW214 | D9: =RI1-AI2 | E9: G0104T3 | F9: 粉碎机 | G9: 测温3 | H9: 4-20MA
B10: 1 | C10: PIW216 | D10: =RI1-AI3 | F10: 备用 | H10: 4-20MA
B11: 2 | C11: PIW218 | D11: =RI1-AI3 | F11: 备用 | H11: 4-20MA
B12: 3 | C12: PIW220 | D12: =RI1-AI3 | F12: 备用 | H12: 4-20MA
B13: 4 | C13: PIW222 | D13: =RI1-AI3 | F13: 备用 | H13: 4-20MA
B17: 输入
B18: 序号 | C18: 地址 | D18: 符号表 | E18: 设备编号 | F18: 设备名称 | G18: 信号名称 | H18: 设备名称（英文） | I18: 信号名称（英文） | J18: 标签 | K18: 备注 | L18: 柜号
A19: 1 | B19: 1 | C19: I200.0 | D19: =RI1-DI01 | E19: =TRIM(MID(SUBSTITUTE($J19,":",REPT(" ",40)),1,40)) -> R0101 | F19: =TRIM(MID(SUBSTITUTE($J19,":",REPT(" ",40)),40,40)) -> 提升机 | G19: =TRIM(MID(SUBSTITUTE($J19,":",REPT(" ",40)),80,40)) -> 运行 | H19: =TRIM(MID(SUBSTITUTE($J19,":",REPT(" ",40)),120,40)) -> Elevator | I19: =TRIM(MID(SUBSTITUTE($J19,":",REPT(" ",40)),160,40)) -> Running | J19: R0101:提升机:运行:Elevator:Running | M19: ¶ | N19: - | O19: =D19 -> =RI1-DI01 | P19: =A19 -> 1 | Q19: =C19 -> I200.0 | R19: =E19&M19&F19&G19&M19&H19&I19 -> R0101¶提升机运行¶ElevatorRunning
A20: 2 | B20: 2 | C20: I200.1 | D20: =RI1-DI01 | E20: =TRIM(MID(SUBSTITUTE($J20,":",REPT(" ",40)),1,40)) -> R0101 | F20: =TRIM(MID(SUBSTITUTE($J20,":",REPT(" ",40)),40,40)) -> 提升机 | G20: =TRIM(MID(SUBSTITUTE($J20,":",REPT(" ",40)),80,40)) -> 急停 | H20: =TRIM(MID(SUBSTITUTE($J20,":",REPT(" ",40)),120,40)) -> Elevator | I20: =TRIM(MID(SUBSTITUTE($J20,":",REPT(" ",40)),160,40)) -> Estop | J20: R0101:提升机:急停:Elevator:Estop | M20: ¶ | N20: - | O20: =D20 -> =RI1-DI01 | P20: =A20 -> 2 | Q20: =C20 -> I200.1 | R20: =E20&M20&F20&G20&M20&H20&I20 -> R0101¶提升机急停¶ElevatorEstop
A21: 3 | B21: 3 | C21: I200.2 | D21: =RI1-DI01 | E21: =TRIM(MID(SUBSTITUTE($J21,":",REPT(" ",40)),1,40)) -> R0102 | F21: =TRIM(MID(SUBSTITUTE($J21,":",REPT(" ",40)),40,40)) -> 刮板机 | G21: =TRIM(MID(SUBSTITUTE($J21,":",REPT(" ",40)),80,40)) -> 运行 | H21: =TRIM(MID(SUBSTITUTE($J21,":",REPT(" ",40)),120,40)) -> Conveyor | I21: =TRIM(MID(SUBSTITUTE($J21,":",REPT(" ",40)),160,40)) -> Running | J21: R0102:刮板机:运行:Conveyor:Running | M21: ¶ | N21: - | O21: =D21 -> =RI1-DI01 | P21: =A21 -> 3 | Q21: =C21 -> I200.2 | R21: =E21&M21&F21&G21&M21&H21&I21 -> R0102¶刮板机运行¶ConveyorRunning
A22: 4 | B22: 4 | C22: I200.3 | D22: =RI1-DI01 | E22: =TRIM(MID(SUBSTITUTE($J22,":",REPT(" ",40)),1,40)) -> R0102 | F22: =TRIM(MID(SUBSTITUTE($J22,":",REPT(" ",40)),40,40)) -> 刮板机 | G22: =TRIM(MID(SUBSTITUTE($J22,":",REPT(" ",40)),80,40)) -> 急停 | H22: =TRIM(MID(SUBSTITUTE($J22,":",REPT(" ",40)),120,40)) -> Conveyor | I22: =TRIM(MID(SUBSTITUTE($J22,":",REPT(" ",40)),160,40)) -> Estop | J22: R0102:刮板机:急停:Conveyor:Estop | M22: ¶ | N22: - | O22: =D22 -> =RI1-DI01 | P22: =A22 -> 4 | Q22: =C22 -> I200.3 | R22: =E22&M22&F22&G22&M22&H22&I22 -> R0102¶刮板机急停¶ConveyorEstop
A23: 5 | B23: 5 | C23: I200.4 | D23: =RI1-DI01 | E23: =TRIM(MID(SUBSTITUTE($J23,":",REPT(" ",40)),1,40)) -> R0105 | F23: =TRIM(MID(SUBSTITUTE($J23,":",REPT(" ",40)),40,40)) -> 旋转分配器 | G23: =TRIM(MID(SUBSTITUTE($J23,":",REPT(" ",40)),80,40)) -> 运行 | H23: =TRIM(MID(SUBSTITUTE($J23,":",REPT(" ",40)),120,40)) -> Rotary Distributor | I23: =TRIM(MID(SUBSTITUTE($J23,":",REPT(" ",40)),160,40)) -> Running | J23: R0105:旋转分配器:运行:Rotary Distributor:Running | M23: ¶ | N23: - | O23: =D23 -> =RI1-DI01 | P23: =A23 -> 5 | Q23: =C23 -> I200.4 | R23: =E23&M23&F23&G23&M23&H23&I23 -> R0105¶旋转分配器运行¶Rotary DistributorRunning
A24: 6 | B24: 6 | C24: I200.5 | D24: =RI1-DI01 | E24: =TRIM(MID(SUBSTITUTE($J24,":",REPT(" ",40)),1,40)) -> R0203 | F24: =TRIM(MID(SUBSTITUTE($J24,":",REPT(" ",40)),40,40)) -> 风机 | G24: =TRIM(MID(SUBSTITUTE($J24,":",REPT(" ",40)),80,40)) -> 运行 | H24: =TRIM(MID(SUBSTITUTE($J24,":",REPT(" ",40)),120,40)) -> Fan | I24: =TRIM(MID(SUBSTITUTE($J24,":",REPT(" ",40)),160,40)) -> Running | J24: R0203:风机:运行:Fan:Running | M24: ¶ | N24: - | O24: =D24 -> =RI1-DI01 | P24: =A24 -> 6 | Q24: =C24 -> I200.5 | R24: =E24&M24&F24&G24&M24&H24&I24 -> R0203¶风机运行¶FanRunning
A25: 7 | B25: 7 | C25: I200.6 | D25: =RI1-DI01 | E25: =TRIM(MID(SUBSTITUTE($J25,":",REPT(" ",40)),1,40)) -> R0205 | F25: =TRIM(MID(SUBSTITUTE($J25,":",REPT(" ",40)),40,40)) -> 刮板机 | G25: =TRIM(MID(SUBSTITUTE($J25,":",REPT(" ",40)),80,40)) -> 运行 | H25: =TRIM(MID(SUBSTITUTE($J25,":",REPT(" ",40)),120,40)) -> Conveyor | I25: =TRIM(MID(SUBSTITUTE($J25,":",REPT(" ",40)),160,40)) -> Running | J25: R0205:刮板机:运行:Conveyor:Running | M25: ¶ | N25: - | O25: =D25 -> =RI1-DI01 | P25: =A25 -> 7 | Q25: =C25 -> I200.6 | R25: =E25&M25&F25&G25&M25&H25&I25 -> R0205¶刮板机运行¶ConveyorRunning
A26: 8 | B26: 8 | C26: I200.7 | D26: =RI1-DI01 | E26: =TRIM(MID(SUBSTITUTE($J26,":",REPT(" ",40)),1,40)) -> R0205 | F26: =TRIM(MID(SUBSTITUTE($J26,":",REPT(" ",40)),40,40)) -> 刮板机 | G26: =TRIM(MID(SUBSTITUTE($J26,":",REPT(" ",40)),80,40)) -> 急停 | H26: =TRIM(MID(SUBSTITUTE($J26,":",REPT(" ",40)),120,40)) -> Conveyor | I26: =TRIM(MID(SUBSTITUTE($J26,":",REPT(" ",40)),160,40)) -> Estop | J26: R0205:刮板机:急停:Conveyor:Estop | M26: ¶ | N26: - | O26: =D26 -> =RI1-DI01 | P26: =A26 -> 8 | Q26: =C26 -> I200.7 | R26: =E26&M26&F26&G26&M26&H26&I26 -> R0205¶刮板机急停¶ConveyorEstop
A27: 9 | B27: 9 | C27: I201.0 | D27: =RI1-DI01 | E27: =TRIM(MID(SUBSTITUTE($J27,":",REPT(" ",40)),1,40)) -> R0206 | F27: =TRIM(MID(SUBSTITUTE($J27,":",REPT(" ",40)),40,40)) -> 提升机 | G27: =TRIM(MID(SUBSTITUTE($J27,":",REPT(" ",40)),80,40)) -> 运行 | H27: =TRIM(MID(SUBSTITUTE($J27,":",REPT(" ",40)),120,40)) -> Elevator | I27: =TRIM(MID(SUBSTITUTE($J27,":",REPT(" ",40)),160,40)) -> Running | J27: R0206:提升机:运行:Elevator:Running | M27: ¶ | N27: - | O27: =D27 -> =RI1-DI01 | P27: =A27 -> 9 | Q27: =C27 -> I201.0 | R27: =E27&M27&F27&G27&M27&H27&I27 -> R0206¶提升机运行¶ElevatorRunning
A28: 10 | B28: 10 | C28: I201.1 | D28: =RI1-DI01 | E28: =TRIM(MID(SUBSTITUTE($J28,":",REPT(" ",40)),1,40)) -> R0206 | F28: =TRIM(MID(SUBSTITUTE($J28,":",REPT(" ",40)),40,40)) -> 提升机 | G28: =TRIM(MID(SUBSTITUTE($J28,":",REPT(" ",40)),80,40)) -> 急停 | H28: =TRIM(MID(SUBSTITUTE($J28,":",REPT(" ",40)),120,40)) -> Elevator | I28: =TRIM(MID(SUBSTITUTE($J28,":",REPT(" ",40)),160,40)) -> Estop | J28: R0206:提升机:急停:Elevator:Estop | M28: ¶ | N28: - | O28: =D28 -> =RI1-DI01 | P28: =A28 -> 10 | Q28: =C28 -> I201.1 | R28: =E28&M28&F28&G28&M28&H28&I28 -> R0206¶提升机急停¶ElevatorEstop
A29: 11 | B29: 11 | C29: I201.2 | D29: =RI1-DI01 | E29: =TRIM(MID(SUBSTITUTE($J29,":",REPT(" ",40)),1,40)) -> R0207 | F29: =TRIM(MID(SUBSTITUTE($J29,":",REPT(" ",40)),40,40)) -> 初清筛 | G29: =TRIM(MID(SUBSTITUTE($J29,":",REPT(" ",40)),80,40)) -> 运行 | H29: =TRIM(MID(SUBSTITUTE($J29,":",REPT(" ",40)),120,40)) -> Precleaner | I29: =TRIM(MID(SUBSTITUTE($J29,":",REPT(" ",40)),160,40)) -> Running | J29: R0207:初清筛:运行:Precleaner:Running | M29: ¶ | N29: - | O29: =D29 -> =RI1-DI01 | P29: =A29 -> 11 | Q29: =C29 -> I201.2 | R29: =E29&M29&F29&G29&M29&H29&I29 -> R0207¶初清筛运行¶PrecleanerRunning
A30: 12 | B30: 12 | C30: I201.3 | D30: =RI1-DI01 | E30: =TRIM(MID(SUBSTITUTE($J30,":",REPT(" ",40)),1,40)) -> R0207 | F30: =TRIM(MID(SUBSTITUTE($J30,":",REPT(" ",40)),40,40)) -> 初清筛 | G30: =TRIM(MID(SUBSTITUTE($J30,":",REPT(" ",40)),80,40)) -> 急停 | H30: =TRIM(MID(SUBSTITUTE($J30,":",REPT(" ",40)),120,40)) -> Precleaner | I30: =TRIM(MID(SUBSTITUTE($J30,":",REPT(" ",40)),160,40)) -> Estop | J30: R0207:初清筛:急停:Precleaner:Estop | M30: ¶ | N30: - | O30: =D30 -> =RI1-DI01 | P30: =A30 -> 12 | Q30: =C30 -> I201.3 | R30: =E30&M30&F30&G30&M30&H30&I30 -> R0207¶初清筛急停¶PrecleanerEstop
... A72: 6 | B72: 54 | C72: I206.5 | D72: =RI1-DI04 | E72: =TRIM(MID(SUBSTITUTE($J72,":",REPT(" ",40)),1,40)) -> G0104_1 | F72: =TRIM(MID(SUBSTITUTE($J72,":",REPT(" ",40)),40,40)) -> 绞龙 | G72: =TRIM(MID(SUBSTITUTE($J72,":",REPT(" ",40)),80,40)) -> 反转到位 | H72: =TRIM(MID(SUBSTITUTE($J72,":",REPT(" ",40)),120,40)) -> Conveyor | I72: =TRIM(MID(SUBSTITUTE($J72,":",REPT(" ",40)),160,40)) -> REV.Limit | J72: G0104_1:绞龙:反转到位:Conveyor:REV.Limit | M72: ¶ | N72: - | O72: =D72 -> =RI1-DI04 | P72: =A72 -> 6 | Q72: =C72 -> I206.5 | R72: =E72&M72&F72&G72&M72&H72&I72 -> G0104_1¶绞龙反转到位¶ConveyorREV.Limit
A73: 7 | B73: 55 | C73: I206.6 | D73: =RI1-DI04 | E73: G0104_1 | F73: 绞龙进中到位信号 | G73: 新增20231123 | H73: =TRIM(MID(SUBSTITUTE($J73,":",REPT(" ",40)),120,40)) -> Conveyor | I73: =TRIM(MID(SUBSTITUTE($J73,":",REPT(" ",40)),160,40)) -> FOR. Limit | J73: G0104_2:绞龙:正转到位:Conveyor:FOR. Limit | M73: ¶ | N73: - | O73: =D73 -> =RI1-DI04 | P73: =A73 -> 7 | Q73: =C73 -> I206.6 | R73: =E73&M73&F73&G73&M73&H73&I73 -> G0104_1¶绞龙进中到位信号新增20231123¶ConveyorFOR. Limit
A74: 8 | B74: 56 | C74: I206.7 | D74: =RI1-DI04 | E74: =TRIM(MID(SUBSTITUTE($J74,":",REPT(" ",40)),1,40)) -> G0104_2 | F74: =TRIM(MID(SUBSTITUTE($J74,":",REPT(" ",40)),40,40)) -> 绞龙 | G74: 运行 | H74: =TRIM(MID(SUBSTITUTE($J74,":",REPT(" ",40)),120,40)) -> Conveyor | I74: =TRIM(MID(SUBSTITUTE($J74,":",REPT(" ",40)),160,40)) -> REV.Limit | J74: G0104_2:绞龙:反转到位:Conveyor:REV.Limit | M74: ¶ | N74: - | O74: =D74 -> =RI1-DI04 | P74: =A74 -> 8 | Q74: =C74 -> I206.7 | R74: =E74&M74&F74&G74&M74&H74&I74 -> G0104_2¶绞龙运行¶ConveyorREV.Limit
A75: 9 | B75: 57 | C75: I207.0 | D75: =RI1-DI04 | E75: =TRIM(MID(SUBSTITUTE($J75,":",REPT(" ",40)),1,40)) -> G0104_3 | F75: =TRIM(MID(SUBSTITUTE($J75,":",REPT(" ",40)),40,40)) -> 粉碎机 | G75: =TRIM(MID(SUBSTITUTE($J75,":",REPT(" ",40)),80,40)) -> 合闸 | H75: =TRIM(MID(SUBSTITUTE($J75,":",REPT(" ",40)),120,40)) -> Grinder | I75: =TRIM(MID(SUBSTITUTE($J75,":",REPT(" ",40)),160,40)) -> Breaker ON | J75: G0104_3:粉碎机:合闸:Grinder:Breaker ON | M75: ¶ | N75: - | O75: =D75 -> =RI1-DI04 | P75: =A75 -> 9 | Q75: =C75 -> I207.0 | R75: =E75&M75&F75&G75&M75&H75&I75 -> G0104_3¶粉碎机合闸¶GrinderBreaker ON
A76: 10 | B76: 58 | C76: I207.1 | D76: =RI1-DI04 | E76: =TRIM(MID(SUBSTITUTE($J76,":",REPT(" ",40)),1,40)) -> G0104_3 | F76: =TRIM(MID(SUBSTITUTE($J76,":",REPT(" ",40)),40,40)) -> 粉碎机 | G76: =TRIM(MID(SUBSTITUTE($J76,":",REPT(" ",40)),80,40)) -> 运行 | H76: =TRIM(MID(SUBSTITUTE($J76,":",REPT(" ",40)),120,40)) -> Grinder | I76: =TRIM(MID(SUBSTITUTE($J76,":",REPT(" ",40)),160,40)) -> Running | J76: G0104_3:粉碎机:运行:Grinder:Running | M76: ¶ | N76: - | O76: =D76 -> =RI1-DI04 | P76: =A76 -> 10 | Q76: =C76 -> I207.1 | R76: =E76&M76&F76&G76&M76&H76&I76 -> G0104_3¶粉碎机运行¶GrinderRunning
A77: 11 | B77: 59 | C77: I207.2 | D77: =RI1-DI04 | E77: =TRIM(MID(SUBSTITUTE($J77,":",REPT(" ",40)),1,40)) -> G0104_3 | F77: =TRIM(MID(SUBSTITUTE($J77,":",REPT(" ",40)),40,40)) -> 粉碎机 | G77: =TRIM(MID(SUBSTITUTE($J77,":",REPT(" ",40)),80,40)) -> 急停 | H77: =TRIM(MID(SUBSTITUTE($J77,":",REPT(" ",40)),120,40)) -> Grinder | I77: =TRIM(MID(SUBSTITUTE($J77,":",REPT(" ",40)),160,40)) -> Estop | J77: G0104_3:粉碎机:急停:Grinder:Estop | M77: ¶ | N77: - | O77: =D77 -> =RI1-DI04 | P77: =A77 -> 11 | Q77: =C77 -> I207.2 | R77: =E77&M77&F77&G77&M77&H77&I77 -> G0104_3¶粉碎机急停¶GrinderEstop
A78: 12 | B78: 60 | C78: I207.3 | D78: =RI1-DI04 | E78: =TRIM(MID(SUBSTITUTE($J78,":",REPT(" ",40)),1,40)) -> G0104_3 | F78: =TRIM(MID(SUBSTITUTE($J78,":",REPT(" ",40)),40,40)) -> 粉碎机 | G78: =TRIM(MID(SUBSTITUTE($J78,":",REPT(" ",40)),80,40)) -> 门保 | H78: =TRIM(MID(SUBSTITUTE($J78,":",REPT(" ",40)),120,40)) -> Grinder | I78: =TRIM(MID(SUBSTITUTE($J78,":",REPT(" ",40)),160,40)) -> Door Protect | J78: G0104_3:粉碎机:门保:Grinder:Door Protect | M78: ¶ | N78: - | O78: =D78 -> =RI1-DI04 | P78: =A78 -> 12 | Q78: =C78 -> I207.3 | R78: =E78&M78&F78&G78&M78&H78&I78 -> G0104_3¶粉碎机门保¶GrinderDoor Protect
A79: 13 | B79: 61 | C79: I207.4 | D79: =RI1-DI04 | E79: =TRIM(MID(SUBSTITUTE($J79,":",REPT(" ",40)),1,40)) -> G0104_3V | F79: =TRIM(MID(SUBSTITUTE($J79,":",REPT(" ",40)),40,40)) -> 粉碎机导向阀 | G79: =TRIM(MID(SUBSTITUTE($J79,":",REPT(" ",40)),80,40)) -> 开门到位 | H79: =TRIM(MID(SUBSTITUTE($J79,":",REPT(" ",40)),120,40)) -> Grinder Valve | I79: =TRIM(MID(SUBSTITUTE($J79,":",REPT(" ",40)),160,40)) -> Openning | J79: G0104_3V:粉碎机导向阀:开门到位:Grinder Valve:Openning | M79: ¶ | N79: - | O79: =D79 -> =RI1-DI04 | P79: =A79 -> 13 | Q79: =C79 -> I207.4 | R79: =E79&M79&F79&G79&M79&H79&I79 -> G0104_3V¶粉碎机导向阀开门到位¶Grinder ValveOpenning
A80: 14 | B80: 62 | C80: I207.5 | D80: =RI1-DI04 | E80: =TRIM(MID(SUBSTITUTE($J80,":",REPT(" ",40)),1,40)) -> G0104_3V | F80: =TRIM(MID(SUBSTITUTE($J80,":",REPT(" ",40)),40,40)) -> 粉碎机导向阀 | G80: =TRIM(MID(SUBSTITUTE($J80,":",REPT(" ",40)),80,40)) -> 关门到位 | H80: =TRIM(MID(SUBSTITUTE($J80,":",REPT(" ",40)),120,40)) -> Grinder Valve | I80: =TRIM(MID(SUBSTITUTE($J80,":",REPT(" ",40)),160,40)) -> Closing | J80: G0104_3V:粉碎机导向阀:关门到位:Grinder Valve:Closing | M80: ¶ | N80: - | O80: =D80 -> =RI1-DI04 | P80: =A80 -> 14 | Q80: =C80 -> I207.5 | R80: =E80&M80&F80&G80&M80&H80&I80 -> G0104_3V¶粉碎机导向阀关门到位¶Grinder ValveClosing
A81: 15 | B81: 63 | C81: I207.6 | D81: =RI1-DI04 | E81: =TRIM(MID(SUBSTITUTE($J81,":",REPT(" ",40)),1,40)) -> G0104_3 | F81: =TRIM(MID(SUBSTITUTE($J81,":",REPT(" ",40)),40,40)) -> 粉碎机 | G81: =TRIM(MID(SUBSTITUTE($J81,":",REPT(" ",40)),80,40)) -> 软起故障 | H81: =TRIM(MID(SUBSTITUTE($J81,":",REPT(" ",40)),120,40)) -> Grinder | I81: =TRIM(MID(SUBSTITUTE($J81,":",REPT(" ",40)),160,40)) -> Softer Alarm | J81: G0104_3:粉碎机:软起故障:Grinder :Softer Alarm | M81: ¶ | N81: - | O81: =D81 -> =RI1-DI04 | P81: =A81 -> 15 | Q81: =C81 -> I207.6 | R81: =E81&M81&F81&G81&M81&H81&I81 -> G0104_3¶粉碎机软起故障¶GrinderSofter Alarm
A82: 16 | B82: 64 | C82: I207.7 | D82: =RI1-DI04 | E82: =TRIM(MID(SUBSTITUTE($J82,":",REPT(" ",40)),1,40)) -> G0106_1 | F82: =TRIM(MID(SUBSTITUTE($J82,":",REPT(" ",40)),40,40)) -> 除尘器 | G82: =TRIM(MID(SUBSTITUTE($J82,":",REPT(" ",40)),80,40)) -> 运行 | H82: =TRIM(MID(SUBSTITUTE($J82,":",REPT(" ",40)),120,40)) -> FILTER | I82: =TRIM(MID(SUBSTITUTE($J82,":",REPT(" ",40)),160,40)) -> Running | J82: G0106_1:除尘器:运行:FILTER:Running | M82: ¶ | N82: - | O82: =D82 -> =RI1-DI04 | P82: =A82 -> 16 | Q82: =C82 -> I207.7 | R82: =E82&M82&F82&G82&M82&H82&I82 -> G0106_1¶除尘器运行¶FILTERRunning
A83: 1 | B83: 65 | C83: I208.0 | D83: =RI1-DI05 | E83: =TRIM(MID(SUBSTITUTE($J83,":",REPT(" ",40)),1,40)) -> G0106_2 | F83: =TRIM(MID(SUBSTITUTE($J83,":",REPT(" ",40)),40,40)) -> 关风器 | G83: =TRIM(MID(SUBSTITUTE($J83,":",REPT(" ",40)),80,40)) -> 运行 | H83: =TRIM(MID(SUBSTITUTE($J83,":",REPT(" ",40)),120,40)) -> Airlock | I83: =TRIM(MID(SUBSTITUTE($J83,":",REPT(" ",40)),160,40)) -> Running | J83: G0106_2:关风器:运行:Airlock:Running | M83: ¶ | N83: - | O83: =D83 -> =RI1-DI05 | P83: =A83 -> 1 | Q83: =C83 -> I208.0 | R83: =E83&M83&F83&G83&M83&H83&I83 -> G0106_2¶关风器运行¶AirlockRunning
A84: 2 | B84: 66 | C84: I208.1 | D84: =RI1-DI05 | E84: =TRIM(MID(SUBSTITUTE($J84,":",REPT(" ",40)),1,40)) -> G0106_3 | F84: =TRIM(MID(SUBSTITUTE($J84,":",REPT(" ",40)),40,40)) -> 扫灰电机 | G84: =TRIM(MID(SUBSTITUTE($J84,":",REPT(" ",40)),80,40)) -> 运行 | H84: =TRIM(MID(SUBSTITUTE($J84,":",REPT(" ",40)),120,40)) -> Cleaning motor | I84: =TRIM(MID(SUBSTITUTE($J84,":",REPT(" ",40)),160,40)) -> Running | J84: G0106_3:扫灰电机:运行:Cleaning motor:Running | M84: ¶ | N84: - | O84: =D84 -> =RI1-DI05 | P84: =A84 -> 2 | Q84: =C84 -> I208.1 | R84: =E84&M84&F84&G84&M84&H84&I84 -> G0106_3¶扫灰电机运行¶Cleaning motorRunning
...

Sheet MCC3-4
B1: 序号 | C1: 地址 | D1: 符号表 | E1: 设备编号 | F1: 设备名称 | G1: 信号名称 | H1: 备注
B2: 1 | C2: PIW224 | D2: 2AI1 | E2: 2G0102_2 | F2: 超微粉碎机 | G2: 电流检测 | H2: 4-20MA
B3: 2 | C3: PIW226 | D3: 2AI1 | E3: 2G0110 | F3: 风机 | G3: 电流检测 | H3: 4-20MA
B4: 3 | C4: PIW228 | D4: 2AI1 | E4: 2G0113 | F4: 提升机 | G4: 电流检测 | H4: 4-20MA
B5: 4 | C5: PIW230 | D5: 2AI1 | E5: 2G0202_2 | F5: 超微粉碎机 | G5: 电流检测 | H5: 4-20MA
B6: 1 | C6: PIW232 | D6: 2AI2 | E6: 2G0210 | F6: 风机 | G6: 电流检测 | H6: 4-20MA
B7: 2 | C7: PIW234 | D7: 2AI2 | E7: 2G0213 | F7: 提升机 | G7: 电流检测 | H7: 4-20MA
B8: 3 | C8: PIW236 | D8: 2AI2 | F8: 备用 | H8: 4-20MA
B9: 4 | C9: PIW238 | D9: 2AI2 | F9: 备用 | H9: 4-20MA
B10: 1 | C10: PIW240 | F10: 备用 | H10: 4-20MA
B11: 2 | C11: PIW242 | D11: 2AI3 | E11: 2G0102_2T2 | F11: 超微粉碎机 | G11: 温度2 | H11: 4-20MA
B12: 3 | C12: PIW244 | D12: 2AI3 | E12: 2G0202_2T1 | F12: 超微粉碎机 | G12: 温度1 | H12: 4-20MA
B13: 4 | C13: PIW246 | D13: 2AI3 | E13: 2G0202_2T2 | F13: 超微粉碎机 | G13: 温度2 | H13: 4-20MA
B16: 输入
B17: 序号 | C17: 地址 | D17: 符号表 | E17: 设备编号 | F17: 设备名称 | G17: 信号名称 | H17: 设备名称（英文） | I17: 信号名称（英文） | J17: 标签 | K17: 备注 | L17: 柜号
A18: 1 | B18: 1 | C18: I212.0 | D18: =RI2-DI01 | E18: =TRIM(MID(SUBSTITUTE($J18,":",REPT(" ",40)),1,40)) -> 2G0101 | F18: =TRIM(MID(SUBSTITUTE($J18,":",REPT(" ",40)),40,40)) -> 喂料器 | G18: =TRIM(MID(SUBSTITUTE($J18,":",REPT(" ",40)),80,40)) -> 运行 | H18: =TRIM(MID(SUBSTITUTE($J18,":",REPT(" ",40)),120,40)) -> Feeder | I18: =TRIM(MID(SUBSTITUTE($J18,":",REPT(" ",40)),160,40)) -> Running | J18: 2G0101:喂料器:运行:Feeder:Running | M18: ¶ | N18: - | O18: =D18 -> =RI2-DI01 | P18: =A18 -> 1 | Q18: =C18 -> I212.0 | R18: =E18&M18&F18&G18&M18&H18&I18 -> 2G0101¶喂料器运行¶FeederRunning
A19: 2 | B19: 2 | C19: I212.1 | D19: =RI2-DI01 | E19: =TRIM(MID(SUBSTITUTE($J19,":",REPT(" ",40)),1,40)) -> 2G0102_1 | F19: =TRIM(MID(SUBSTITUTE($J19,":",REPT(" ",40)),40,40)) -> 分级轮 | G19: =TRIM(MID(SUBSTITUTE($J19,":",REPT(" ",40)),80,40)) -> 运行 | H19: =TRIM(MID(SUBSTITUTE($J19,":",REPT(" ",40)),120,40)) -> Grading motor | I19: =TRIM(MID(SUBSTITUTE($J19,":",REPT(" ",40)),160,40)) -> Running | J19: 2G0102_1:分级轮:运行:Grading motor:Running | M19: ¶ | N19: - | O19: =D19 -> =RI2-DI01 | P19: =A19 -> 2 | Q19: =C19 -> I212.1 | R19: =E19&M19&F19&G19&M19&H19&I19 -> 2G0102_1¶分级轮运行¶Grading motorRunning
A20: 3 | B20: 3 | C20: I212.2 | D20: =RI2-DI01 | E20: =TRIM(MID(SUBSTITUTE($J20,":",REPT(" ",40)),1,40)) -> 2G0102_2 | F20: =TRIM(MID(SUBSTITUTE($J20,":",REPT(" ",40)),40,40)) -> 超微粉碎机 | G20: =TRIM(MID(SUBSTITUTE($J20,":",REPT(" ",40)),80,40)) -> 合闸 | H20: =TRIM(MID(SUBSTITUTE($J20,":",REPT(" ",40)),120,40)) -> Pulverizer | I20: =TRIM(MID(SUBSTITUTE($J20,":",REPT(" ",40)),160,40)) -> Breaker ON | J20: 2G0102_2:超微粉碎机:合闸:Pulverizer:Breaker ON | M20: ¶ | N20: - | O20: =D20 -> =RI2-DI01 | P20: =A20 -> 3 | Q20: =C20 -> I212.2 | R20: =E20&M20&F20&G20&M20&H20&I20 -> 2G0102_2¶超微粉碎机合闸¶PulverizerBreaker ON
A21: 4 | B21: 4 | C21: I212.3 | D21: =RI2-DI01 | E21: =TRIM(MID(SUBSTITUTE($J21,":",REPT(" ",40)),1,40)) -> 2G0102_2 | F21: =TRIM(MID(SUBSTITUTE($J21,":",REPT(" ",40)),40,40)) -> 超微粉碎机 | G21: =TRIM(MID(SUBSTITUTE($J21,":",REPT(" ",40)),80,40)) -> 运行 | H21: =TRIM(MID(SUBSTITUTE($J21,":",REPT(" ",40)),120,40)) -> Pulverizer | I21: =TRIM(MID(SUBSTITUTE($J21,":",REPT(" ",40)),160,40)) -> Running | J21: 2G0102_2:超微粉碎机:运行:Pulverizer:Running | M21: ¶ | N21: - | O21: =D21 -> =RI2-DI01 | P21: =A21 -> 4 | Q21: =C21 -> I212.3 | R21: =E21&M21&F21&G21&M21&H21&I21 -> 2G0102_2¶超微粉碎机运行¶PulverizerRunning
A22: 5 | B22: 5 | C22: I212.4 | D22: =RI2-DI01 | E22: =TRIM(MID(SUBSTITUTE($J22,":",REPT(" ",40)),1,40)) -> 2G0102_2 | F22: =TRIM(MID(SUBSTITUTE($J22,":",REPT(" ",40)),40,40)) -> 超微粉碎机 | G22: =TRIM(MID(SUBSTITUTE($J22,":",REPT(" ",40)),80,40)) -> 急停 | H22: =TRIM(MID(SUBSTITUTE($J22,":",REPT(" ",40)),120,40)) -> Pulverizer | I22: =TRIM(MID(SUBSTITUTE($J22,":",REPT(" ",40)),160,40)) -> Estop | J22: 2G0102_2:超微粉碎机:急停:Pulverizer:Estop | M22: ¶ | N22: - | O22: =D22 -> =RI2-DI01 | P22: =A22 -> 5 | Q22: =C22 -> I212.4 | R22: =E22&M22&F22&G22&M22&H22&I22 -> 2G0102_2¶超微粉碎机急停¶PulverizerEstop
A23: 6 | B23: 6 | C23: I212.5 | D23: =RI2-DI01 | E23: =TRIM(MID(SUBSTITUTE($J23,":",REPT(" ",40)),1,40)) -> 2G0102_2 | F23: =TRIM(MID(SUBSTITUTE($J23,":",REPT(" ",40)),40,40)) -> 超微粉碎机 | G23: =TRIM(MID(SUBSTITUTE($J23,":",REPT(" ",40)),80,40)) -> 软起故障 | H23: =TRIM(MID(SUBSTITUTE($J23,":",REPT(" ",40)),120,40)) -> Pulverizer | I23: =TRIM(MID(SUBSTITUTE($J23,":",REPT(" ",40)),160,40)) -> Softer Alar | J23: 2G0102_2:超微粉碎机:软起故障:Pulverizer :Softer Alarm | M23: ¶ | N23: - | O23: =D23 -> =RI2-DI01 | P23: =A23 -> 6 | Q23: =C23 -> I212.5 | R23: =E23&M23&F23&G23&M23&H23&I23 -> 2G0102_2¶超微粉碎机软起故障¶PulverizerSofter Alar
A24: 7 | B24: 7 | C24: I212.6 | D24: =RI2-DI01 | E24: =TRIM(MID(SUBSTITUTE($J24,":",REPT(" ",40)),1,40)) -> 2G0102_2 | F24: =TRIM(MID(SUBSTITUTE($J24,":",REPT(" ",40)),40,40)) -> 超微粉碎机 | G24: =TRIM(MID(SUBSTITUTE($J24,":",REPT(" ",40)),80,40)) -> 门保 | H24: =TRIM(MID(SUBSTITUTE($J24,":",REPT(" ",40)),120,40)) -> Pulverizer | I24: =TRIM(MID(SUBSTITUTE($J24,":",REPT(" ",40)),160,40)) -> Door Protect | J24: 2G0102_2:超微粉碎机:门保:Pulverizer:Door Protect | M24: ¶ | N24: - | O24: =D24 -> =RI2-DI01 | P24: =A24 -> 7 | Q24: =C24 -> I212.6 | R24: =E24&M24&F24&G24&M24&H24&I24 -> 2G0102_2¶超微粉碎机门保¶PulverizerDoor Protect
A25: 8 | B25: 8 | C25: I212.7 | D25: =RI2-DI01 | E25: =TRIM(MID(SUBSTITUTE($J25,":",REPT(" ",40)),1,40)) -> 2G0102_3 | F25: =TRIM(MID(SUBSTITUTE($J25,":",REPT(" ",40)),40,40)) -> 液压 | G25: =TRIM(MID(SUBSTITUTE($J25,":",REPT(" ",40)),80,40)) -> 运行 | H25: =TRIM(MID(SUBSTITUTE($J25,":",REPT(" ",40)),120,40)) -> Oil pump | I25: =TRIM(MID(SUBSTITUTE($J25,":",REPT(" ",40)),160,40)) -> Running | J25: 2G0102_3:液压:运行:Oil pump:Running | M25: ¶ | N25: - | O25: =D25 -> =RI2-DI01 | P25: =A25 -> 8 | Q25: =C25 -> I212.7 | R25: =E25&M25&F25&G25&M25&H25&I25 -> 2G0102_3¶液压运行¶Oil pumpRunning
A26: 9 | B26: 9 | C26: I213.0 | D26: =RI2-DI01 | E26: =TRIM(MID(SUBSTITUTE($J26,":",REPT(" ",40)),1,40)) -> 2G0106 | F26: =TRIM(MID(SUBSTITUTE($J26,":",REPT(" ",40)),40,40)) -> 关风器 | G26: =TRIM(MID(SUBSTITUTE($J26,":",REPT(" ",40)),80,40)) -> 运行 | H26: =TRIM(MID(SUBSTITUTE($J26,":",REPT(" ",40)),120,40)) -> Airlock | I26: =TRIM(MID(SUBSTITUTE($J26,":",REPT(" ",40)),160,40)) -> Running | J26: 2G0106:关风器:运行:Airlock:Running | M26: ¶ | N26: - | O26: =D26 -> =RI2-DI01 | P26: =A26 -> 9 | Q26: =C26 -> I213.0 | R26: =E26&M26&F26&G26&M26&H26&I26 -> 2G0106¶关风器运行¶AirlockRunning
A27: 10 | B27: 10 | C27: I213.1 | D27: =RI2-DI01 | E27: =TRIM(MID(SUBSTITUTE($J27,":",REPT(" ",40)),1,40)) -> 2G0107_1 | F27: =TRIM(MID(SUBSTITUTE($J27,":",REPT(" ",40)),40,40)) -> 关风器 | G27: =TRIM(MID(SUBSTITUTE($J27,":",REPT(" ",40)),80,40)) -> 运行 | H27: =TRIM(MID(SUBSTITUTE($J27,":",REPT(" ",40)),120,40)) -> Airlock | I27: =TRIM(MID(SUBSTITUTE($J27,":",REPT(" ",40)),160,40)) -> Running | J27: 2G0107_1:关风器:运行:Airlock:Running | M27: ¶ | N27: - | O27: =D27 -> =RI2-DI01 | P27: =A27 -> 10 | Q27: =C27 -> I213.1 | R27: =E27&M27&F27&G27&M27&H27&I27 -> 2G0107_1¶关风器运行¶AirlockRunning
A28: 11 | B28: 11 | C28: I213.2 | D28: =RI2-DI01 | E28: =TRIM(MID(SUBSTITUTE($J28,":",REPT(" ",40)),1,40)) -> 2G0107_2 | F28: =TRIM(MID(SUBSTITUTE($J28,":",REPT(" ",40)),40,40)) -> 扫灰电机 | G28: =TRIM(MID(SUBSTITUTE($J28,":",REPT(" ",40)),80,40)) -> 运行 | H28: =TRIM(MID(SUBSTITUTE($J28,":",REPT(" ",40)),120,40)) -> Cleaning motor | I28: =TRIM(MID(SUBSTITUTE($J28,":",REPT(" ",40)),160,40)) -> Running | J28: 2G0107_2:扫灰电机:运行:Cleaning motor:Running | M28: ¶ | N28: - | O28: =D28 -> =RI2-DI01 | P28: =A28 -> 11 | Q28: =C28 -> I213.2 | R28: =E28&M28&F28&G28&M28&H28&I28 -> 2G0107_2¶扫灰电机运行¶Cleaning motorRunning
A29: 12 | B29: 12 | C29: I213.3 | D29: =RI2-DI01 | E29: =TRIM(MID(SUBSTITUTE($J29,":",REPT(" ",40)),1,40)) -> 2G0110 | F29: =TRIM(MID(SUBSTITUTE($J29,":",REPT(" ",40)),40,40)) -> 风机 | G29: =TRIM(MID(SUBSTITUTE($J29,":",REPT(" ",40)),80,40)) -> 运行 | H29: =TRIM(MID(SUBSTITUTE($J29,":",REPT(" ",40)),120,40)) -> Fan | I29: =TRIM(MID(SUBSTITUTE($J29,":",REPT(" ",40)),160,40)) -> Running | J29: 2G0110:风机:运行:Fan:Running | M29: ¶ | N29: - | O29: =D29 -> =RI2-DI01 | P29: =A29 -> 12 | Q29: =C29 -> I213.3 | R29: =E29&M29&F29&G29&M29&H29&I29 -> 2G0110¶风机运行¶FanRunning
... A63: 14 | B63: 46 | C63: I217.5 | D63: =RI2-DI03 | E63: =TRIM(MID(SUBSTITUTE($J63,":",REPT(" ",40)),1,40)) -> 2G0217 | F63: =TRIM(MID(SUBSTITUTE($J63,":",REPT(" ",40)),40,40)) -> 高方筛(功率待定) | G63: =TRIM(MID(SUBSTITUTE($J63,":",REPT(" ",40)),80,40)) -> 急停 | H63: =TRIM(MID(SUBSTITUTE($J63,":",REPT(" ",40)),120,40)) -> Plansifter | I63: =TRIM(MID(SUBSTITUTE($J63,":",REPT(" ",40)),160,40)) -> Estop | J63: 2G0217:高方筛(功率待定):急停:Plansifter:Estop | M63: ¶ | N63: - | O63: =D63 -> =RI2-DI03 | P63: =A63 -> 14 | Q63: =C63 -> I217.5 | R63: =E63&M63&F63&G63&M63&H63&I63 -> 2G0217¶高方筛(功率待定)急停¶PlansifterEstop
A64: 15 | B64: 47 | C64: I217.6 | D64: =RI2-DI03 | E64: 2G0101 | F64: 喂料器 | G64: 门保 | H64: =TRIM(MID(SUBSTITUTE($J64,":",REPT(" ",40)),120,40)) | I64: =TRIM(MID(SUBSTITUTE($J64,":",REPT(" ",40)),160,40)) | J64: 备用 Spare | M64: ¶ | N64: - | O64: =D64 -> =RI2-DI03 | P64: =A64 -> 15 | Q64: =C64 -> I217.6 | R64: =E64&M64&F64&G64&M64&H64&I64 -> 2G0101¶喂料器门保¶
A65: 16 | B65: 48 | C65: I217.7 | D65: =RI2-DI03 | E65: 2G0201 | F65: 喂料器 | G65: 门保 | H65: =TRIM(MID(SUBSTITUTE($J65,":",REPT(" ",40)),120,40)) | I65: =TRIM(MID(SUBSTITUTE($J65,":",REPT(" ",40)),160,40)) | J65: 备用 Spare | M65: ¶ | N65: - | O65: =D65 -> =RI2-DI03 | P65: =A65 -> 16 | Q65: =C65 -> I217.7 | R65: =E65&M65&F65&G65&M65&H65&I65 -> 2G0201¶喂料器门保¶
A66: 1 | B66: 48 | C66: I218.0
A67: 2 | B67: 48 | C67: I218.1
A68: 3 | B68: 48 | C68: I218.2
A69: 4 | B69: 48 | C69: I218.3
A70: 5 | B70: 48 | C70: I218.4
A71: 6 | B71: 48 | C71: I218.5
A72: 7 | B72: 48 | C72: I218.6
A73: 8 | B73: 48 | C73: I218.7
A74: 9 | B74: 48 | C74: I219.0
A75: 10 | B75: 48 | C75: I219.1
...

Sheet MCC5-6
B1: 序号 | C1: 地址 | D1: 符号表 | E1: 设备编号 | F1: 设备名称 | G1: 信号名称 | H1: 备注
B2: 1 | C2: PIW248 | D2: 3AI1 | E2: M0101 | F2: 混合机 | G2: 电流检测 | H2: 4-20MA
B3: 2 | C3: PIW250 | D3: 3AI1 | E3: M0108 | F3: 提升机 | G3: 电流检测 | H3: 4-20MA
B4: 3 | C4: PIW252 | D4: 3AI1 | F4: 备用 | H4: 4-20MA
B5: 4 | C5: PIW254 | D5: 3AI1 | F5: 备用 | H5: 4-20MA
B6: 1 | C6: PIW256
B7: 2 | C7: PIW258
B8: 3 | C8: PIW260
B9: 4 | C9: PIW262
B10: 1 | C10: PIW264
B11: 2 | C11: PIW266
B12: 3 | C12: PIW268
B13: 4 | C13: PIW270
B19: 输入
B20: 序号 | C20: 地址 | D20: 符号表 | E20: 设备编号 | F20: 设备名称 | G20: 信号名称 | H20: 设备名称（英文） | I20: 信号名称（英文） | J20: 标签 | K20: 备注 | L20: 柜号
A21: 1 | B21: 1 | C21: I220.0 | D21: =RI3-DI01 | E21: =TRIM(MID(SUBSTITUTE($J21,":",REPT(" ",40)),1,40)) -> B0110 | F21: =TRIM(MID(SUBSTITUTE($J21,":",REPT(" ",40)),40,40)) -> 风机 | G21: =TRIM(MID(SUBSTITUTE($J21,":",REPT(" ",40)),80,40)) -> 运行 | H21: =TRIM(MID(SUBSTITUTE($J21,":",REPT(" ",40)),120,40)) -> Fan | I21: =TRIM(MID(SUBSTITUTE($J21,":",REPT(" ",40)),160,40)) -> Running | J21: B0110:风机:运行:Fan:Running | M21: ¶ | N21: - | O21: =D21 -> =RI3-DI01 | P21: =A21 -> 1 | Q21: =C21 -> I220.0 | R21: =E21&M21&F21&G21&M21&H21&I21 -> B0110¶风机运行¶FanRunning
A22: 2 | B22: 2 | C22: I220.1 | D22: =RI3-DI01 | E22: =TRIM(MID(SUBSTITUTE($J22,":",REPT(" ",40)),1,40)) -> M0101 | F22: =TRIM(MID(SUBSTITUTE($J22,":",REPT(" ",40)),40,40)) -> 混合机 | G22: =TRIM(MID(SUBSTITUTE($J22,":",REPT(" ",40)),80,40)) -> 运行 | H22: =TRIM(MID(SUBSTITUTE($J22,":",REPT(" ",40)),120,40)) -> Mixer | I22: =TRIM(MID(SUBSTITUTE($J22,":",REPT(" ",40)),160,40)) -> Running | J22: M0101:混合机:运行:Mixer:Running | M22: ¶ | N22: - | O22: =D22 -> =RI3-DI01 | P22: =A22 -> 2 | Q22: =C22 -> I220.1 | R22: =E22&M22&F22&G22&M22&H22&I22 -> M0101¶混合机运行¶MixerRunning
A23: 3 | B23: 3 | C23: I220.2 | D23: =RI3-DI01 | E23: =TRIM(MID(SUBSTITUTE($J23,":",REPT(" ",40)),1,40)) -> M0101 | F23: =TRIM(MID(SUBSTITUTE($J23,":",REPT(" ",40)),40,40)) -> 混合机 | G23: =TRIM(MID(SUBSTITUTE($J23,":",REPT(" ",40)),80,40)) -> 负荷急停 | H23: =TRIM(MID(SUBSTITUTE($J23,":",REPT(" ",40)),120,40)) -> Mixer | I23: =TRIM(MID(SUBSTITUTE($J23,":",REPT(" ",40)),160,40)) -> Isolate/Estop | J23: M0101:混合机:负荷急停:Mixer:Isolate/Estop | M23: ¶ | N23: - | O23: =D23 -> =RI3-DI01 | P23: =A23 -> 3 | Q23: =C23 -> I220.2 | R23: =E23&M23&F23&G23&M23&H23&I23 -> M0101¶混合机负荷急停¶MixerIsolate/Estop
A24: 4 | B24: 4 | C24: I220.3 | D24: =RI3-DI01 | E24: =TRIM(MID(SUBSTITUTE($J24,":",REPT(" ",40)),1,40)) -> M0101V1 | F24: =TRIM(MID(SUBSTITUTE($J24,":",REPT(" ",40)),40,40)) -> 混合机门 | G24: =TRIM(MID(SUBSTITUTE($J24,":",REPT(" ",40)),80,40)) -> 开门到位 | H24: =TRIM(MID(SUBSTITUTE($J24,":",REPT(" ",40)),120,40)) -> Mixer Gate | I24: =TRIM(MID(SUBSTITUTE($J24,":",REPT(" ",40)),160,40)) -> Openning | J24: M0101V1:混合机门:开门到位:Mixer Gate:Openning | M24: ¶ | N24: - | O24: =D24 -> =RI3-DI01 | P24: =A24 -> 4 | Q24: =C24 -> I220.3 | R24: =E24&M24&F24&G24&M24&H24&I24 -> M0101V1¶混合机门开门到位¶Mixer GateOpenning
A25: 5 | B25: 5 | C25: I220.4 | D25: =RI3-DI01 | E25: =TRIM(MID(SUBSTITUTE($J25,":",REPT(" ",40)),1,40)) -> M0101V1 | F25: =TRIM(MID(SUBSTITUTE($J25,":",REPT(" ",40)),40,40)) -> 混合机门 | G25: =TRIM(MID(SUBSTITUTE($J25,":",REPT(" ",40)),80,40)) -> 关门到位 | H25: =TRIM(MID(SUBSTITUTE($J25,":",REPT(" ",40)),120,40)) -> Mixer Gate | I25: =TRIM(MID(SUBSTITUTE($J25,":",REPT(" ",40)),160,40)) -> Closing | J25: M0101V1:混合机门:关门到位:Mixer Gate:Closing | M25: ¶ | N25: - | O25: =D25 -> =RI3-DI01 | P25: =A25 -> 5 | Q25: =C25 -> I220.4 | R25: =E25&M25&F25&G25&M25&H25&I25 -> M0101V1¶混合机门关门到位¶Mixer GateClosing
A26: 6 | B26: 6 | C26: I220.5 | D26: =RI3-DI01 | E26: =TRIM(MID(SUBSTITUTE($J26,":",REPT(" ",40)),1,40)) -> M0101 | F26: =TRIM(MID(SUBSTITUTE($J26,":",REPT(" ",40)),40,40)) -> 混合机 | G26: =TRIM(MID(SUBSTITUTE($J26,":",REPT(" ",40)),80,40)) -> 门保 | H26: =TRIM(MID(SUBSTITUTE($J26,":",REPT(" ",40)),120,40)) -> Mixer | I26: =TRIM(MID(SUBSTITUTE($J26,":",REPT(" ",40)),160,40)) -> Door Protect | J26: M0101:混合机:门保:Mixer:Door Protect | M26: ¶ | N26: - | O26: =D26 -> =RI3-DI01 | P26: =A26 -> 6 | Q26: =C26 -> I220.5 | R26: =E26&M26&F26&G26&M26&H26&I26 -> M0101¶混合机门保¶MixerDoor Protect
A27: 7 | B27: 7 | C27: I220.6 | D27: =RI3-DI01 | E27: =TRIM(MID(SUBSTITUTE($J27,":",REPT(" ",40)),1,40)) -> M0105 | F27: =TRIM(MID(SUBSTITUTE($J27,":",REPT(" ",40)),40,40)) -> 刮板机 | G27: =TRIM(MID(SUBSTITUTE($J27,":",REPT(" ",40)),80,40)) -> 运行 | H27: =TRIM(MID(SUBSTITUTE($J27,":",REPT(" ",40)),120,40)) -> Conveyor | I27: =TRIM(MID(SUBSTITUTE($J27,":",REPT(" ",40)),160,40)) -> Running | J27: M0105:刮板机:运行:Conveyor:Running | M27: ¶ | N27: - | O27: =D27 -> =RI3-DI01 | P27: =A27 -> 7 | Q27: =C27 -> I220.6 | R27: =E27&M27&F27&G27&M27&H27&I27 -> M0105¶刮板机运行¶ConveyorRunning
A28: 8 | B28: 8 | C28: I220.7 | D28: =RI3-DI01 | E28: =TRIM(MID(SUBSTITUTE($J28,":",REPT(" ",40)),1,40)) -> M0105 | F28: =TRIM(MID(SUBSTITUTE($J28,":",REPT(" ",40)),40,40)) -> 刮板机 | G28: =TRIM(MID(SUBSTITUTE($J28,":",REPT(" ",40)),80,40)) -> 急停 | H28: =TRIM(MID(SUBSTITUTE($J28,":",REPT(" ",40)),120,40)) -> Conveyor | I28: =TRIM(MID(SUBSTITUTE($J28,":",REPT(" ",40)),160,40)) -> Estop | J28: M0105:刮板机:急停:Conveyor:Estop | M28: ¶ | N28: - | O28: =D28 -> =RI3-DI01 | P28: =A28 -> 8 | Q28: =C28 -> I220.7 | R28: =E28&M28&F28&G28&M28&H28&I28 -> M0105¶刮板机急停¶ConveyorEstop
A29: 9 | B29: 9 | C29: I221.0 | D29: =RI3-DI01 | E29: =TRIM(MID(SUBSTITUTE($J29,":",REPT(" ",40)),1,40)) -> M0107 | F29: =TRIM(MID(SUBSTITUTE($J29,":",REPT(" ",40)),40,40)) -> 风机 | G29: =TRIM(MID(SUBSTITUTE($J29,":",REPT(" ",40)),80,40)) -> 运行 | H29: =TRIM(MID(SUBSTITUTE($J29,":",REPT(" ",40)),120,40)) -> Fan | I29: =TRIM(MID(SUBSTITUTE($J29,":",REPT(" ",40)),160,40)) -> Running | J29: M0107:风机:运行:Fan:Running | M29: ¶ | N29: - | O29: =D29 -> =RI3-DI01 | P29: =A29 -> 9 | Q29: =C29 -> I221.0 | R29: =E29&M29&F29&G29&M29&H29&I29 -> M0107¶风机运行¶FanRunning
A30: 10 | B30: 10 | C30: I221.1 | D30: =RI3-DI01 | E30: =TRIM(MID(SUBSTITUTE($J30,":",REPT(" ",40)),1,40)) -> M0108 | F30: =TRIM(MID(SUBSTITUTE($J30,":",REPT(" ",40)),40,40)) -> 提升机 | G30: =TRIM(MID(SUBSTITUTE($J30,":",REPT(" ",40)),80,40)) -> 运行 | H30: =TRIM(MID(SUBSTITUTE($J30,":",REPT(" ",40)),120,40)) -> Elevator | I30: =TRIM(MID(SUBSTITUTE($J30,":",REPT(" ",40)),160,40)) -> Running | J30: M0108:提升机:运行:Elevator:Running | M30: ¶ | N30: - | O30: =D30 -> =RI3-DI01 | P30: =A30 -> 10 | Q30: =C30 -> I221.1 | R30: =E30&M30&F30&G30&M30&H30&I30 -> M0108¶提升机运行¶ElevatorRunning
A31: 11 | B31: 11 | C31: I221.2 | D31: =RI3-DI01 | E31: =TRIM(MID(SUBSTITUTE($J31,":",REPT(" ",40)),1,40)) -> M0108 | F31: =TRIM(MID(SUBSTITUTE($J31,":",REPT(" ",40)),40,40)) -> 提升机 | G31: =TRIM(MID(SUBSTITUTE($J31,":",REPT(" ",40)),80,40)) -> 急停 | H31: =TRIM(MID(SUBSTITUTE($J31,":",REPT(" ",40)),120,40)) -> Elevator | I31: =TRIM(MID(SUBSTITUTE($J31,":",REPT(" ",40)),160,40)) -> Estop | J31: M0108:提升机:急停:Elevator:Estop | M31: ¶ | N31: - | O31: =D31 -> =RI3-DI01 | P31: =A31 -> 11 | Q31: =C31 -> I221.2 | R31: =E31&M31&F31&G31&M31&H31&I31 -> M0108¶提升机急停¶ElevatorEstop
A32: 12 | B32: 12 | C32: I221.3 | D32: =RI3-DI01 | E32: =TRIM(MID(SUBSTITUTE($J32,":",REPT(" ",40)),1,40)) -> M0110 | F32: =TRIM(MID(SUBSTITUTE($J32,":",REPT(" ",40)),40,40)) -> 初清筛 | G32: =TRIM(MID(SUBSTITUTE($J32,":",REPT(" ",40)),80,40)) -> 运行 | H32: =TRIM(MID(SUBSTITUTE($J32,":",REPT(" ",40)),120,40)) -> Precleaner | I32: =TRIM(MID(SUBSTITUTE($J32,":",REPT(" ",40)),160,40)) -> Running | J32: M0110:初清筛:运行:Precleaner:Running | M32: ¶ | N32: - | O32: =D32 -> =RI3-DI01 | P32: =A32 -> 12 | Q32: =C32 -> I221.3 | R32: =E32&M32&F32&G32&M32&H32&I32 -> M0110¶初清筛运行¶PrecleanerRunning
... A64: 12 | B64: 44 | C64: I225.3 | D64: =RI3-DI03 | E64: =TRIM(MID(SUBSTITUTE($J64,":",REPT(" ",40)),1,40)) -> AG-4101 | F64: =TRIM(MID(SUBSTITUTE($J64,":",REPT(" ",40)),40,40)) -> 搅拌电机 | G64: =TRIM(MID(SUBSTITUTE($J64,":",REPT(" ",40)),80,40)) -> 运行 | H64: =TRIM(MID(SUBSTITUTE($J64,":",REPT(" ",40)),120,40)) -> Stir motor | I64: =TRIM(MID(SUBSTITUTE($J64,":",REPT(" ",40)),160,40)) -> Running | J64: AG-4101:搅拌电机:运行:Stir motor:Running | M64: ¶ | N64: - | O64: =D64 -> =RI3-DI03 | P64: =A64 -> 12 | Q64: =C64 -> I225.3 | R64: =E64&M64&F64&G64&M64&H64&I64 -> AG-4101¶搅拌电机运行¶Stir motorRunning
A65: 13 | B65: 45 | C65: I225.4 | D65: =RI3-DI03 | E65: =TRIM(MID(SUBSTITUTE($J65,":",REPT(" ",40)),1,40)) -> WPU-1001 | F65: =TRIM(MID(SUBSTITUTE($J65,":",REPT(" ",40)),40,40)) -> 水泵 | G65: =TRIM(MID(SUBSTITUTE($J65,":",REPT(" ",40)),80,40)) -> 运行 | H65: =TRIM(MID(SUBSTITUTE($J65,":",REPT(" ",40)),120,40)) -> Water pump | I65: =TRIM(MID(SUBSTITUTE($J65,":",REPT(" ",40)),160,40)) -> Running | J65: WPU-1001:水泵:运行:Water pump:Running | M65: ¶ | N65: - | O65: =D65 -> =RI3-DI03 | P65: =A65 -> 13 | Q65: =C65 -> I225.4 | R65: =E65&M65&F65&G65&M65&H65&I65 -> WPU-1001¶水泵运行¶Water pumpRunning | S65: 取消 | T65: 2023.5.29
A66: 14 | B66: 46 | C66: I225.5 | D66: =RI3-DI03 | E66: =TRIM(MID(SUBSTITUTE($J66,":",REPT(" ",40)),1,40)) -> WPU-1002 | F66: =TRIM(MID(SUBSTITUTE($J66,":",REPT(" ",40)),40,40)) -> 水泵 | G66: =TRIM(MID(SUBSTITUTE($J66,":",REPT(" ",40)),80,40)) -> 运行 | H66: =TRIM(MID(SUBSTITUTE($J66,":",REPT(" ",40)),120,40)) -> Water pump | I66: =TRIM(MID(SUBSTITUTE($J66,":",REPT(" ",40)),160,40)) -> Running | J66: WPU-1002:水泵:运行:Water pump:Running | M66: ¶ | N66: - | O66: =D66 -> =RI3-DI03 | P66: =A66 -> 14 | Q66: =C66 -> I225.5 | R66: =E66&M66&F66&G66&M66&H66&I66 -> WPU-1002¶水泵运行¶Water pumpRunning | S66: 取消 | T66: 2023.5.29
A67: 15 | B67: 47 | C67: I225.6 | D67: =RI3-DI03 | E67: =TRIM(MID(SUBSTITUTE($J67,":",REPT(" ",40)),1,40)) -> WPU-1003 | F67: =TRIM(MID(SUBSTITUTE($J67,":",REPT(" ",40)),40,40)) -> 水泵 | G67: =TRIM(MID(SUBSTITUTE($J67,":",REPT(" ",40)),80,40)) -> 运行 | H67: =TRIM(MID(SUBSTITUTE($J67,":",REPT(" ",40)),120,40)) -> Water pump | I67: =TRIM(MID(SUBSTITUTE($J67,":",REPT(" ",40)),160,40)) -> Running | J67: WPU-1003:水泵:运行:Water pump:Running | M67: ¶ | N67: - | O67: =D67 -> =RI3-DI03 | P67: =A67 -> 15 | Q67: =C67 -> I225.6 | R67: =E67&M67&F67&G67&M67&H67&I67 -> WPU-1003¶水泵运行¶Water pumpRunning | S67: 取消 | T67: 2023.5.29
A68: 16 | B68: 48 | C68: I225.7 | D68: =RI3-DI03 | E68: =TRIM(MID(SUBSTITUTE($J68,":",REPT(" ",40)),1,40)) -> WPU-2001 | F68: =TRIM(MID(SUBSTITUTE($J68,":",REPT(" ",40)),40,40)) -> 水泵 | G68: =TRIM(MID(SUBSTITUTE($J68,":",REPT(" ",40)),80,40)) -> 运行 | H68: =TRIM(MID(SUBSTITUTE($J68,":",REPT(" ",40)),120,40)) -> Water pump | I68: =TRIM(MID(SUBSTITUTE($J68,":",REPT(" ",40)),160,40)) -> Running | J68: WPU-2001:水泵:运行:Water pump:Running | M68: ¶ | N68: - | O68: =D68 -> =RI3-DI03 | P68: =A68 -> 16 | Q68: =C68 -> I225.7 | R68: =E68&M68&F68&G68&M68&H68&I68 -> WPU-2001¶水泵运行¶Water pumpRunning | S68: 取消 | T68: 2023.5.29
A69: 1 | B69: 49 | C69: I226.0 | D69: =RI3-DI04 | E69: =TRIM(MID(SUBSTITUTE($J69,":",REPT(" ",40)),1,40)) -> WPU-2002 | F69: =TRIM(MID(SUBSTITUTE($J69,":",REPT(" ",40)),40,40)) -> 水泵 | G69: =TRIM(MID(SUBSTITUTE($J69,":",REPT(" ",40)),80,40)) -> 运行 | H69: =TRIM(MID(SUBSTITUTE($J69,":",REPT(" ",40)),120,40)) -> Water pump | I69: =TRIM(MID(SUBSTITUTE($J69,":",REPT(" ",40)),160,40)) -> Running | J69: WPU-2002:水泵:运行:Water pump:Running | M69: ¶ | N69: - | O69: =D69 -> =RI3-DI04 | P69: =A69 -> 1 | Q69: =C69 -> I226.0 | R69: =E69&M69&F69&G69&M69&H69&I69 -> WPU-2002¶水泵运行¶Water pumpRunning | S69: 取消 | T69: 2023.5.29
A70: 2 | B70: 50 | C70: I226.1 | D70: =RI3-DI04 | E70: =TRIM(MID(SUBSTITUTE($J70,":",REPT(" ",40)),1,40)) -> WPU-2003 | F70: =TRIM(MID(SUBSTITUTE($J70,":",REPT(" ",40)),40,40)) -> 水泵 | G70: =TRIM(MID(SUBSTITUTE($J70,":",REPT(" ",40)),80,40)) -> 运行 | H70: =TRIM(MID(SUBSTITUTE($J70,":",REPT(" ",40)),120,40)) -> Water pump | I70: =TRIM(MID(SUBSTITUTE($J70,":",REPT(" ",40)),160,40)) -> Running | J70: WPU-2003:水泵:运行:Water pump:Running | M70: ¶ | N70: - | O70: =D70 -> =RI3-DI04 | P70: =A70 -> 2 | Q70: =C70 -> I226.1 | R70: =E70&M70&F70&G70&M70&H70&I70 -> WPU-2003¶水泵运行¶Water pumpRunning | S70: 取消 | T70: 2023.5.29
A71: 3 | B71: 51 | C71: I226.2 | D71: =RI3-DI04 | E71: =TRIM(MID(SUBSTITUTE($J71,":",REPT(" ",40)),1,40)) -> FAN-2004 | F71: =TRIM(MID(SUBSTITUTE($J71,":",REPT(" ",40)),40,40)) -> 冷却风机 | G71: =TRIM(MID(SUBSTITUTE($J71,":",REPT(" ",40)),80,40)) -> 运行 | H71: =TRIM(MID(SUBSTITUTE($J71,":",REPT(" ",40)),120,40)) -> FAN | I71: =TRIM(MID(SUBSTITUTE($J71,":",REPT(" ",40)),160,40)) -> Running | J71: FAN-2004:冷却风机:运行:FAN:Running | M71: ¶ | N71: - | O71: =D71 -> =RI3-DI04 | P71: =A71 -> 3 | Q71: =C71 -> I226.2 | R71: =E71&M71&F71&G71&M71&H71&I71 -> FAN-2004¶冷却风机运行¶FANRunning | S71: 取消 | T71: 2023.5.29
A72: 4 | B72: 52 | C72: I226.3 | D72: =RI3-DI04 | E72: =TRIM(MID(SUBSTITUTE($J72,":",REPT(" ",40)),1,40)) -> 备用 Spare | F72: =TRIM(MID(SUBSTITUTE($J72,":",REPT(" ",40)),40,40)) | G72: =TRIM(MID(SUBSTITUTE($J72,":",REPT(" ",40)),80,40)) | H72: =TRIM(MID(SUBSTITUTE($J72,":",REPT(" ",40)),120,40)) | I72: =TRIM(MID(SUBSTITUTE($J72,":",REPT(" ",40)),160,40)) | J72: 备用 Spare | M72: ¶ | N72: - | O72: =D72 -> =RI3-DI04 | P72: =A72 -> 4 | Q72: =C72 -> I226.3 | R72: =E72&M72&F72&G72&M72&H72&I72 -> 备用 Spare¶¶
A73: 5 | B73: 53 | C73: I226.4 | D73: =RI3-DI04 | E73: =TRIM(MID(SUBSTITUTE($J73,":",REPT(" ",40)),1,40)) -> 备用 Spare | F73: =TRIM(MID(SUBSTITUTE($J73,":",REPT(" ",40)),40,40)) | G73: =TRIM(MID(SUBSTITUTE($J73,":",REPT(" ",40)),80,40)) | H73: =TRIM(MID(SUBSTITUTE($J73,":",REPT(" ",40)),120,40)) | I73: =TRIM(MID(SUBSTITUTE($J73,":",REPT(" ",40)),160,40)) | J73: 备用 Spare | M73: ¶ | N73: - | O73: =D73 -> =RI3-DI04 | P73: =A73 -> 5 | Q73: =C73 -> I226.4 | R73: =E73&M73&F73&G73&M73&H73&I73 -> 备用 Spare¶¶
A74: 6 | B74: 54 | C74: I226.5 | D74: =RI3-DI04 | E74: =TRIM(MID(SUBSTITUTE($J74,":",REPT(" ",40)),1,40)) -> 备用 Spare | F74: =TRIM(MID(SUBSTITUTE($J74,":",REPT(" ",40)),40,40)) | G74: =TRIM(MID(SUBSTITUTE($J74,":",REPT(" ",40)),80,40)) | H74: =TRIM(MID(SUBSTITUTE($J74,":",REPT(" ",40)),120,40)) | I74: =TRIM(MID(SUBSTITUTE($J74,":",REPT(" ",40)),160,40)) | J74: 备用 Spare | M74: ¶ | N74: - | O74: =D74 -> =RI3-DI04 | P74: =A74 -> 6 | Q74: =C74 -> I226.5 | R74: =E74&M74&F74&G74&M74&H74&I74 -> 备用 Spare¶¶
A75: 7 | B75: 55 | C75: I226.6 | D75: =RI3-DI04 | E75: =TRIM(MID(SUBSTITUTE($J75,":",REPT(" ",40)),1,40)) -> 备用 Spare | F75: =TRIM(MID(SUBSTITUTE($J75,":",REPT(" ",40)),40,40)) | G75: =TRIM(MID(SUBSTITUTE($J75,":",REPT(" ",40)),80,40)) | H75: =TRIM(MID(SUBSTITUTE($J75,":",REPT(" ",40)),120,40)) | I75: =TRIM(MID(SUBSTITUTE($J75,":",REPT(" ",40)),160,40)) | J75: 备用 Spare | M75: ¶ | N75: - | O75: =D75 -> =RI3-DI04 | P75: =A75 -> 7 | Q75: =C75 -> I226.6 | R75: =E75&M75&F75&G75&M75&H75&I75 -> 备用 Spare¶¶
A76: 8 | B76: 56 | C76: I226.7 | D76: =RI3-DI04 | E76: =TRIM(MID(SUBSTITUTE($J76,":",REPT(" ",40)),1,40)) -> 备用 Spare | F76: =TRIM(MID(SUBSTITUTE($J76,":",REPT(" ",40)),40,40)) | G76: =TRIM(MID(SUBSTITUTE($J76,":",REPT(" ",40)),80,40)) | H76: =TRIM(MID(SUBSTITUTE($J76,":",REPT(" ",40)),120,40)) | I76: =TRIM(MID(SUBSTITUTE($J76,":",REPT(" ",40)),160,40)) | J76: 备用 Spare | M76: ¶ | N76: - | O76: =D76 -> =RI3-DI04 | P76: =A76 -> 8 | Q76: =C76 -> I226.7 | R76: =E76&M76&F76&G76&M76&H76&I76 -> 备用 Spare¶¶
...

Sheet MCC7-8
B1: 序号 | C1: 地址 | D1: 符号表 | E1: 设备编号 | F1: 设备名称 | G1: 信号名称 | H1: 备注
B2: 1 | C2: PIW272 | D2: 4AI1 | E2: G0203_3 | F2: 粉碎机 | G2: 电流检测 | H2: 4-20MA
B3: 5 | C3: PIW274 | D3: 4AI1 | E3: G0207 | F3: 粉碎风机 | G3: 电流检测 | H3: 4-20MA
B4: 3 | C4: PIW276 | D4: 4AI1 | E4: 2M0113 | F4: 混合机 | G4: 电流检测 | H4: 4-20MA
B5: 7 | C5: PIW278 | D5: 4AI1 | E5: 2M0121 | F5: 提升机 | G5: 电流检测 | H5: 4-20MA
B6: 1 | C6: PIW280 | D6: 4AI2 | E6: HL0106 | F6: 提升机 | G6: 电流检测 | H6: 4-20MA
B7: 5 | C7: PIW282 | D7: 4AI2 | E7: HL0117 | F7: 混合机 | G7: 电流检测 | H7: 4-20MA
B8: 3 | C8: PIW284 | D8: 4AI2 | F8: 备用 | H8: 4-20MA
B9: 7 | C9: PIW286 | D9: 4AI2 | F9: 备用 | H9: 4-20MA
B10: 1 | C10: PIW288 | D10: 4AI3 | F10: 备用 | H10: 4-20MA
B11: 5 | C11: PIW290 | D11: 4AI3 | E11: G0303T1 | F11: 粉碎机 | G11: 测温1 | H11: 4-20MA
B12: 3 | C12: PIW292 | D12: 4AI3 | E12: G0303T2 | F12: 粉碎机 | G12: 测温2 | H12: 4-20MA
B13: 7 | C13: PIW294 | D13: 4AI3 | E13: G0303T3 | F13: 粉碎机 | G13: 测温3 | H13: 4-20MA
B19: 输入
B20: 序号 | C20: 地址 | D20: 符号表 | E20: 设备编号 | F20: 设备名称 | G20: 信号名称 | H20: 设备名称（英文） | I20: 信号名称（英文） | J20: 标签 | K20: 备注 | L20: 柜号
A21: 1 | B21: 1 | C21: I228.0 | D21: =RI4-DI01 | E21: =TRIM(MID(SUBSTITUTE($J21,":",REPT(" ",40)),1,40)) -> G0202 | F21: =TRIM(MID(SUBSTITUTE($J21,":",REPT(" ",40)),40,40)) -> 喂料器 | G21: =TRIM(MID(SUBSTITUTE($J21,":",REPT(" ",40)),80,40)) -> 运行 | H21: =TRIM(MID(SUBSTITUTE($J21,":",REPT(" ",40)),120,40)) -> Feeder | I21: =TRIM(MID(SUBSTITUTE($J21,":",REPT(" ",40)),160,40)) -> Running | J21: G0202:喂料器:运行:Feeder:Running | M21: ¶ | N21: - | O21: =D21 -> =RI4-DI01 | P21: =A21 -> 1 | Q21: =C21 -> I228.0 | R21: =E21&M21&F21&G21&M21&H21&I21 -> G0202¶喂料器运行¶FeederRunning
A22: 2 | B22: 2 | C22: I228.1 | D22: =RI4-DI01 | E22: =TRIM(MID(SUBSTITUTE($J22,":",REPT(" ",40)),1,40)) -> G0203_1 | F22: =TRIM(MID(SUBSTITUTE($J22,":",REPT(" ",40)),40,40)) -> 绞龙 | G22: =TRIM(MID(SUBSTITUTE($J22,":",REPT(" ",40)),80,40)) -> 正转到位 | H22: =TRIM(MID(SUBSTITUTE($J22,":",REPT(" ",40)),120,40)) -> Conveyor | I22: =TRIM(MID(SUBSTITUTE($J22,":",REPT(" ",40)),160,40)) -> FOR. Limit | J22: G0203_1:绞龙:正转到位:Conveyor:FOR. Limit | M22: ¶ | N22: - | O22: =D22 -> =RI4-DI01 | P22: =A22 -> 2 | Q22: =C22 -> I228.1 | R22: =E22&M22&F22&G22&M22&H22&I22 -> G0203_1¶绞龙正转到位¶ConveyorFOR. Limit
A23: 3 | B23: 3 | C23: I228.2 | D23: =RI4-DI01 | E23: =TRIM(MID(SUBSTITUTE($J23,":",REPT(" ",40)),1,40)) -> G0203_1 | F23: =TRIM(MID(SUBSTITUTE($J23,":",REPT(" ",40)),40,40)) -> 绞龙 | G23: =TRIM(MID(SUBSTITUTE($J23,":",REPT(" ",40)),80,40)) -> 反转到位 | H23: =TRIM(MID(SUBSTITUTE($J23,":",REPT(" ",40)),120,40)) -> Conveyor | I23: =TRIM(MID(SUBSTITUTE($J23,":",REPT(" ",40)),160,40)) -> REV.Limit | J23: G0203_1:绞龙:反转到位:Conveyor:REV.Limit | M23: ¶ | N23: - | O23: =D23 -> =RI4-DI01 | P23: =A23 -> 3 | Q23: =C23 -> I228.2 | R23: =E23&M23&F23&G23&M23&H23&I23 -> G0203_1¶绞龙反转到位¶ConveyorREV.Limit
A24: 4 | B24: 4 | C24: I228.3 | D24: =RI4-DI01 | E24: G0203-S2- | F24: 绞龙接近开关 | G24: 绞龙进中到位信号 | H24: 新增20231123 | I24: =TRIM(MID(SUBSTITUTE($J24,":",REPT(" ",40)),160,40)) -> FOR. Limit | J24: G0203_2:绞龙:正转到位:Conveyor:FOR. Limit | M24: ¶ | N24: - | O24: =D24 -> =RI4-DI01 | P24: =A24 -> 4 | Q24: =C24 -> I228.3 | R24: =#REF!&M24&#REF!&#REF!&M24&#REF!&I24 -> #REF!
A25: 5 | B25: 5 | C25: I228.4 | D25: =RI4-DI01 | E25: =TRIM(MID(SUBSTITUTE($J25,":",REPT(" ",40)),1,40)) -> G0203_2 | F25: =TRIM(MID(SUBSTITUTE($J25,":",REPT(" ",40)),40,40)) -> 绞龙 | G25: 运行 | H25: =TRIM(MID(SUBSTITUTE($J25,":",REPT(" ",40)),120,40)) -> Conveyor | I25: =TRIM(MID(SUBSTITUTE($J25,":",REPT(" ",40)),160,40)) -> REV.Limit | J25: G0203_2:绞龙:反转到位:Conveyor:REV.Limit | M25: ¶ | N25: - | O25: =D25 -> =RI4-DI01 | P25: =A25 -> 5 | Q25: =C25 -> I228.4 | R25: =E25&M25&F25&G25&M25&H25&I25 -> G0203_2¶绞龙运行¶ConveyorREV.Limit
A26: 6 | B26: 6 | C26: I228.5 | D26: =RI4-DI01 | E26: =TRIM(MID(SUBSTITUTE($J26,":",REPT(" ",40)),1,40)) -> G0203_3 | F26: =TRIM(MID(SUBSTITUTE($J26,":",REPT(" ",40)),40,40)) -> 粉碎机 | G26: =TRIM(MID(SUBSTITUTE($J26,":",REPT(" ",40)),80,40)) -> 合闸 | H26: =TRIM(MID(SUBSTITUTE($J26,":",REPT(" ",40)),120,40)) -> Grinder | I26: =TRIM(MID(SUBSTITUTE($J26,":",REPT(" ",40)),160,40)) -> Breaker ON | J26: G0203_3:粉碎机:合闸:Grinder:Breaker ON | M26: ¶ | N26: - | O26: =D26 -> =RI4-DI01 | P26: =A26 -> 6 | Q26: =C26 -> I228.5 | R26: =E26&M26&F26&G26&M26&H26&I26 -> G0203_3¶粉碎机合闸¶GrinderBreaker ON
A27: 7 | B27: 7 | C27: I228.6 | D27: =RI4-DI01 | E27: =TRIM(MID(SUBSTITUTE($J27,":",REPT(" ",40)),1,40)) -> G0203_3 | F27: =TRIM(MID(SUBSTITUTE($J27,":",REPT(" ",40)),40,40)) -> 粉碎机 | G27: =TRIM(MID(SUBSTITUTE($J27,":",REPT(" ",40)),80,40)) -> 运行 | H27: =TRIM(MID(SUBSTITUTE($J27,":",REPT(" ",40)),120,40)) -> Grinder | I27: =TRIM(MID(SUBSTITUTE($J27,":",REPT(" ",40)),160,40)) -> Running | J27: G0203_3:粉碎机:运行:Grinder:Running | M27: ¶ | N27: - | O27: =D27 -> =RI4-DI01 | P27: =A27 -> 7 | Q27: =C27 -> I228.6 | R27: =E27&M27&F27&G27&M27&H27&I27 -> G0203_3¶粉碎机运行¶GrinderRunning
A28: 8 | B28: 8 | C28: I228.7 | D28: =RI4-DI01 | E28: =TRIM(MID(SUBSTITUTE($J28,":",REPT(" ",40)),1,40)) -> G0203_3 | F28: =TRIM(MID(SUBSTITUTE($J28,":",REPT(" ",40)),40,40)) -> 粉碎机 | G28: =TRIM(MID(SUBSTITUTE($J28,":",REPT(" ",40)),80,40)) -> 急停 | H28: =TRIM(MID(SUBSTITUTE($J28,":",REPT(" ",40)),120,40)) -> Grinder | I28: =TRIM(MID(SUBSTITUTE($J28,":",REPT(" ",40)),160,40)) -> Estop | J28: G0203_3:粉碎机:急停:Grinder:Estop | M28: ¶ | N28: - | O28: =D28 -> =RI4-DI01 | P28: =A28 -> 8 | Q28: =C28 -> I228.7 | R28: =E28&M28&F28&G28&M28&H28&I28 -> G0203_3¶粉碎机急停¶GrinderEstop
A29: 9 | B29: 9 | C29: I229.0 | D29: =RI4-DI01 | E29: =TRIM(MID(SUBSTITUTE($J29,":",REPT(" ",40)),1,40)) -> G0203_3 | F29: =TRIM(MID(SUBSTITUTE($J29,":",REPT(" ",40)),40,40)) -> 粉碎机 | G29: =TRIM(MID(SUBSTITUTE($J29,":",REPT(" ",40)),80,40)) -> 门保 | H29: =TRIM(MID(SUBSTITUTE($J29,":",REPT(" ",40)),120,40)) -> Grinder | I29: =TRIM(MID(SUBSTITUTE($J29,":",REPT(" ",40)),160,40)) -> Door Protect | J29: G0203_3:粉碎机:门保:Grinder:Door Protect | M29: ¶ | N29: - | O29: =D29 -> =RI4-DI01 | P29: =A29 -> 9 | Q29: =C29 -> I229.0 | R29: =E29&M29&F29&G29&M29&H29&I29 -> G0203_3¶粉碎机门保¶GrinderDoor Protect
A30: 10 | B30: 10 | C30: I229.1 | D30: =RI4-DI01 | E30: =TRIM(MID(SUBSTITUTE($J30,":",REPT(" ",40)),1,40)) -> G0203_3V | F30: =TRIM(MID(SUBSTITUTE($J30,":",REPT(" ",40)),40,40)) -> 粉碎机导向阀 | G30: =TRIM(MID(SUBSTITUTE($J30,":",REPT(" ",40)),80,40)) -> 开门到位 | H30: =TRIM(MID(SUBSTITUTE($J30,":",REPT(" ",40)),120,40)) -> Grinder Valve | I30: =TRIM(MID(SUBSTITUTE($J30,":",REPT(" ",40)),160,40)) -> Openning | J30: G0203_3V:粉碎机导向阀:开门到位:Grinder Valve:Openning | M30: ¶ | N30: - | O30: =D30 -> =RI4-DI01 | P30: =A30 -> 10 | Q30: =C30 -> I229.1 | R30: =E30&M30&F30&G30&M30&H30&I30 -> G0203_3V¶粉碎机导向阀开门到位¶Grinder ValveOpenning
A31: 11 | B31: 11 | C31: I229.2 | D31: =RI4-DI01 | E31: =TRIM(MID(SUBSTITUTE($J31,":",REPT(" ",40)),1,40)) -> G0203_3V | F31: =TRIM(MID(SUBSTITUTE($J31,":",REPT(" ",40)),40,40)) -> 粉碎机导向阀 | G31: =TRIM(MID(SUBSTITUTE($J31,":",REPT(" ",40)),80,40)) -> 关门到位 | H31: =TRIM(MID(SUBSTITUTE($J31,":",REPT(" ",40)),120,40)) -> Grinder Valve | I31: =TRIM(MID(SUBSTITUTE($J31,":",REPT(" ",40)),160,40)) -> Closing | J31: G0203_3V:粉碎机导向阀:关门到位:Grinder Valve:Closing | M31: ¶ | N31: - | O31: =D31 -> =RI4-DI01 | P31: =A31 -> 11 | Q31: =C31 -> I229.2 | R31: =E31&M31&F31&G31&M31&H31&I31 -> G0203_3V¶粉碎机导向阀关门到位¶Grinder ValveClosing
A32: 12 | B32: 12 | C32: I229.3 | D32: =RI4-DI01 | E32: =TRIM(MID(SUBSTITUTE($J32,":",REPT(" ",40)),1,40)) -> G0203_3 | F32: =TRIM(MID(SUBSTITUTE($J32,":",REPT(" ",40)),40,40)) -> 粉碎机 | G32: =TRIM(MID(SUBSTITUTE($J32,":",REPT(" ",40)),80,40)) -> 软起故障 | H32: =TRIM(MID(SUBSTITUTE($J32,":",REPT(" ",40)),120,40)) -> Grinder | I32: =TRIM(MID(SUBSTITUTE($J32,":",REPT(" ",40)),160,40)) -> Softer Alarm | J32: G0203_3:粉碎机:软起故障:Grinder :Softer Alarm | M32: ¶ | N32: - | O32: =D32 -> =RI4-DI01 | P32: =A32 -> 12 | Q32: =C32 -> I229.3 | R32: =E32&M32&F32&G32&M32&H32&I32 -> G0203_3¶粉碎机软起故障¶GrinderSofter Alarm
A33: 13 | B33: 13 | C33: I229.4 | D33: =RI4-DI01 | E33: =TRIM(MID(SUBSTITUTE($J33,":",REPT(" ",40)),1,40)) -> G0205_1 | F33: =TRIM(MID(SUBSTITUTE($J33,":",REPT(" ",40)),40,40)) -> 除尘器 | G33: =TRIM(MID(SUBSTITUTE($J33,":",REPT(" ",40)),80,40)) -> 运行 | H33: =TRIM(MID(SUBSTITUTE($J33,":",REPT(" ",40)),120,40)) -> FILTER | I33: =TRIM(MID(SUBSTITUTE($J33,":",REPT(" ",40)),160,40)) -> Running | J33: G0205_1:除尘器:运行:FILTER:Running | M33: ¶ | N33: - | O33: =D33 -> =RI4-DI01 | P33: =A33 -> 13 | Q33: =C33 -> I229.4 | R33: =E33&M33&F33&G33&M33&H33&I33 -> G0205_1¶除尘器运行¶FILTERRunning
A34: 14 | B34: 14 | C34: I229.5 | D34: =RI4-DI01 | E34: =TRIM(MID(SUBSTITUTE($J34,":",REPT(" ",40)),1,40)) -> G0205_2 | F34: =TRIM(MID(SUBSTITUTE($J34,":",REPT(" ",40)),40,40)) -> 关风器 | G34: =TRIM(MID(SUBSTITUTE($J34,":",REPT(" ",40)),80,40)) -> 运行 | H34: =TRIM(MID(SUBSTITUTE($J34,":",REPT(" ",40)),120,40)) -> Airlock | I34: =TRIM(MID(SUBSTITUTE($J34,":",REPT(" ",40)),160,40)) -> Running | J34: G0205_2:关风器:运行:Airlock:Running | M34: ¶ | N34: - | O34: =D34 -> =RI4-DI01 | P34: =A34 -> 14 | Q34: =C34 -> I229.5 | R34: =E34&M34&F34&G34&M34&H34&I34 -> G0205_2¶关风器运行¶AirlockRunning
A35: 15 | B35: 15 | C35: I229.6 | D35: =RI4-DI01 | E35: =TRIM(MID(SUBSTITUTE($J35,":",REPT(" ",40)),1,40)) -> G0205_3 | F35: =TRIM(MID(SUBSTITUTE($J35,":",REPT(" ",40)),40,40)) -> 扫灰电机 | G35: =TRIM(MID(SUBSTITUTE($J35,":",REPT(" ",40)),80,40)) -> 运行 | H35: =TRIM(MID(SUBSTITUTE($J35,":",REPT(" ",40)),120,40)) -> Cleaning motor | I35: =TRIM(MID(SUBSTITUTE($J35,":",REPT(" ",40)),160,40)) -> Running | J35: G0205_3:扫灰电机:运行:Cleaning motor:Running | M35: ¶ | N35: - | O35: =D35 -> =RI4-DI01 | P35: =A35 -> 15 | Q35: =C35 -> I229.6 | R35: =E35&M35&F35&G35&M35&H35&I35 -> G0205_3¶扫灰电机运行¶Cleaning motorRunning
A36: 16 | B36: 16 | C36: I229.7 | D36: =RI4-DI01 | E36: =TRIM(MID(SUBSTITUTE($J36,":",REPT(" ",40)),1,40)) -> G0206 | F36: =TRIM(MID(SUBSTITUTE($J36,":",REPT(" ",40)),40,40)) -> 风门电机 | G36: =TRIM(MID(SUBSTITUTE($J36,":",REPT(" ",40)),80,40)) -> 正转到位 | H36: =TRIM(MID(SUBSTITUTE($J36,":",REPT(" ",40)),120,40)) -> Airdoor | I36: =TRIM(MID(SUBSTITUTE($J36,":",REPT(" ",40)),160,40)) -> FOR. Limit | J36: G0206:风门电机:正转到位:Airdoor:FOR. Limit | M36: ¶ | N36: - | O36: =D36 -> =RI4-DI01 | P36: =A36 -> 16 | Q36: =C36 -> I229.7 | R36: =E36&M36&F36&G36&M36&H36&I36 -> G0206¶风门电机正转到位¶AirdoorFOR. Limit
A37: 1 | B37: 17 | C37: I230.0 | D37: =RI4-DI02 | E37: =TRIM(MID(SUBSTITUTE($J37,":",REPT(" ",40)),1,40)) -> G0206 | F37: =TRIM(MID(SUBSTITUTE($J37,":",REPT(" ",40)),40,40)) -> 风门电机 | G37: =TRIM(MID(SUBSTITUTE($J37,":",REPT(" ",40)),80,40)) -> 中间到位 | H37: =TRIM(MID(SUBSTITUTE($J37,":",REPT(" ",40)),120,40)) -> Airdoor | I37: =TRIM(MID(SUBSTITUTE($J37,":",REPT(" ",40)),160,40)) -> MID. Limit | J37: G0206:风门电机:中间到位:Airdoor:MID. Limit | M37: ¶ | N37: - | O37: =D37 -> =RI4-DI02 | P37: =A37 -> 1 | Q37: =C37 -> I230.0 | R37: =E37&M37&F37&G37&M37&H37&I37 -> G0206¶风门电机中间到位¶AirdoorMID. Limit
... A41: 5 | B41: 21 | C41: I230.4 | D41: =RI4-DI02 | E41: =TRIM(MID(SUBSTITUTE($J41,":",REPT(" ",40)),1,40)) -> G0211 | F41: =TRIM(MID(SUBSTITUTE($J41,":",REPT(" ",40)),40,40)) -> 刮板机 | G41: =TRIM(MID(SUBSTITUTE($J41,":",REPT(" ",40)),80,40)) -> 急停 | H41: =TRIM(MID(SUBSTITUTE($J41,":",REPT(" ",40)),120,40)) -> Conveyor | I41: =TRIM(MID(SUBSTITUTE($J41,":",REPT(" ",40)),160,40)) -> Estop | J41: G0211:刮板机:急停:Conveyor:Estop | M41: ¶ | N41: - | O41: =D41 -> =RI4-DI02 | P41: =A41 -> 5 | Q41: =C41 -> I230.4 | R41: =E41&M41&F41&G41&M41&H41&I41 -> G0211¶刮板机急停¶ConveyorEstop
A42: 6 | B42: 22 | C42: I230.5 | D42: =RI4-DI02 | E42: =TRIM(MID(SUBSTITUTE($J42,":",REPT(" ",40)),1,40)) -> G0203-S1- | F42: 除铁门保 | G42: =TRIM(MID(SUBSTITUTE($J42,":",REPT(" ",40)),80,40)) -> 绞龙接近开关 | H42: =TRIM(MID(SUBSTITUTE($J42,":",REPT(" ",40)),120,40)) -> WORKING POSITION | I42: =TRIM(MID(SUBSTITUTE($J42,":",REPT(" ",40)),160,40)) -> WO | J42: G0203-S1-:绞龙接近开关:绞龙接近开关:WORKING POSITION:WORKING POSITION | M42: ¶ | N42: - | O42: =D42 -> =RI4-DI02 | P42: =A42 -> 6 | Q42: =C42 -> I230.5 | R42: =E42&M42&F42&G42&M42&H42&I42 -> G0203-S1-¶除铁门保绞龙接近开关¶WORKING POSITIONWO
A43: 7 | B43: 23 | C43: I230.6 | D43: =RI4-DI02 | E43: =TRIM(MID(SUBSTITUTE($J43,":",REPT(" ",40)),1,40)) -> G0203-S2- | F43: 风门门保 | G43: =TRIM(MID(SUBSTITUTE($J43,":",REPT(" ",40)),80,40)) -> 绞龙接近开关 | H43: =TRIM(MID(SUBSTITUTE($J43,":",REPT(" ",40)),120,40)) -> CONTROL ON AIR INL | I43: =TRIM(MID(SUBSTITUTE($J43,":",REPT(" ",40)),160,40)) -> ET | J43: G0203-S2-:绞龙接近开关:绞龙接近开关:CONTROL ON AIR INLET:CONTROL ON AIR INLET | M43: ¶ | N43: - | O43: =D43 -> =RI4-DI02 | P43: =A43 -> 7 | Q43: =C43 -> I230.6 | R43: =E43&M43&F43&G43&M43&H43&I43 -> G0203-S2-¶风门门保绞龙接近开关¶CONTROL ON AIR INLET
A44: 8 | B44: 24 | C44: I230.7 | D44: =RI4-DI02 | E44: =TRIM(MID(SUBSTITUTE($J44,":",REPT(" ",40)),1,40)) -> G0203-S3- | F44: =TRIM(MID(SUBSTITUTE($J44,":",REPT(" ",40)),40,40)) -> 喂料斗料位 | G44: =TRIM(MID(SUBSTITUTE($J44,":",REPT(" ",40)),80,40)) -> 喂料斗料位 | H44: =TRIM(MID(SUBSTITUTE($J44,":",REPT(" ",40)),120,40)) -> PRODUCT SENSOR 24VDC | I44: =TRIM(MID(SUBSTITUTE($J44,":",REPT(" ",40)),160,40)) | J44: G0203-S3-:喂料斗料位:喂料斗料位:PRODUCT SENSOR 24VDC:PRODUCT SENSOR 24VDC | M44: ¶ | N44: - | O44: =D44 -> =RI4-DI02 | P44: =A44 -> 8 | Q44: =C44 -> I230.7 | R44: =E44&M44&F44&G44&M44&H44&I44 -> G0203-S3-¶喂料斗料位喂料斗料位¶PRODUCT SENSOR 24VDC
A45: 9 | B45: 25 | C45: I231.0 | D45: =RI4-DI02 | E45: =TRIM(MID(SUBSTITUTE($J45,":",REPT(" ",40)),1,40)) -> G0203-S4- | F45: =TRIM(MID(SUBSTITUTE($J45,":",REPT(" ",40)),40,40)) -> 备用 | G45: =TRIM(MID(SUBSTITUTE($J45,":",REPT(" ",40)),80,40)) -> 备用 | H45: =TRIM(MID(SUBSTITUTE($J45,":",REPT(" ",40)),120,40)) -> SPARE | I45: =TRIM(MID(SUBSTITUTE($J45,":",REPT(" ",40)),160,40)) -> SPARE | J45: G0203-S4-:备用:备用:SPARE:SPARE | M45: ¶ | N45: - | O45: =D45 -> =RI4-DI02 | P45: =A45 -> 9 | Q45: =C45 -> I231.0 | R45: =E45&M45&F45&G45&M45&H45&I45 -> G0203-S4-¶备用备用¶SPARESPARE
A46: 10 | B46: 26 | C46: I231.1 | D46: =RI4-DI02 | E46: =TRIM(MID(SUBSTITUTE($J46,":",REPT(" ",40)),1,40)) -> 2M0101 | F46: =TRIM(MID(SUBSTITUTE($J46,":",REPT(" ",40)),40,40)) -> 刮板机 | G46: =TRIM(MID(SUBSTITUTE($J46,":",REPT(" ",40)),80,40)) -> 运行 | H46: =TRIM(MID(SUBSTITUTE($J46,":",REPT(" ",40)),120,40)) -> Conveyor | I46: =TRIM(MID(SUBSTITUTE($J46,":",REPT(" ",40)),160,40)) -> Running | J46: 2M0101:刮板机:运行:Conveyor:Running | M46: ¶ | N46: - | O46: =D46 -> =RI4-DI02 | P46: =A46 -> 10 | Q46: =C46 -> I231.1 | R46: =E46&M46&F46&G46&M46&H46&I46 -> 2M0101¶刮板机运行¶ConveyorRunning
A47: 11 | B47: 27 | C47: I231.2 | D47: =RI4-DI02 | E47: =TRIM(MID(SUBSTITUTE($J47,":",REPT(" ",40)),1,40)) -> 2M0101 | F47: =TRIM(MID(SUBSTITUTE($J47,":",REPT(" ",40)),40,40)) -> 刮板机 | G47: =TRIM(MID(SUBSTITUTE($J47,":",REPT(" ",40)),80,40)) -> 急停 | H47: =TRIM(MID(SUBSTITUTE($J47,":",REPT(" ",40)),120,40)) -> Conveyor | I47: =TRIM(MID(SUBSTITUTE($J47,":",REPT(" ",40)),160,40)) -> Estop | J47: 2M0101:刮板机:急停:Conveyor:Estop | M47: ¶ | N47: - | O47: =D47 -> =RI4-DI02 | P47: =A47 -> 11 | Q47: =C47 -> I231.2 | R47: =E47&M47&F47&G47&M47&H47&I47 -> 2M0101¶刮板机急停¶ConveyorEstop
A48: 12 | B48: 28 | C48: I231.3 | D48: =RI4-DI02 | E48: =TRIM(MID(SUBSTITUTE($J48,":",REPT(" ",40)),1,40)) -> 2M0107 | F48: =TRIM(MID(SUBSTITUTE($J48,":",REPT(" ",40)),40,40)) -> 风机 | G48: =TRIM(MID(SUBSTITUTE($J48,":",REPT(" ",40)),80,40)) -> 运行 | H48: =TRIM(MID(SUBSTITUTE($J48,":",REPT(" ",40)),120,40)) -> Fan | I48: =TRIM(MID(SUBSTITUTE($J48,":",REPT(" ",40)),160,40)) -> Running | J48: 2M0107:风机:运行:Fan:Running | M48: ¶ | N48: - | O48: =D48 -> =RI4-DI02 | P48: =A48 -> 12 | Q48: =C48 -> I231.3 | R48: =E48&M48&F48&G48&M48&H48&I48 -> 2M0107¶风机运行¶FanRunning
...

Sheet MCC11
B1: 序号 | C1: 地址 | D1: 符号表 | E1: 设备编号 | F1: 设备名称 | G1: 信号名称 | H1: 备注
B2: 1 | C2: PIW1104 | D2: 5AI1 | E2: E0153FM | F2: 流量检测 | H2: 4-20MA
B3: 5 | C3: PIW1106 | D3: 5AI1 | E3: E0153PI | F3: 压力检测 | H3: 4-20MA
B4: 3 | C4: PIW1108 | D4: 5AI1 | E4: E0135提升机 | F4: 电流 | G4: 后加 | H4: 4-20MA
B5: 7 | C5: PIW1110 | D5: 5AI1 | E5: E0175提升机 | F5: 电流 | G5: 后加 | H5: 4-20MA
B6: 1 | C6: PQW1070 | E6: E0135震动 | H6: 4-20MA
B7: 5 | C7: PQW1072 | E7: E0136提升机 | H7: 4-20MA
B8: 3 | C8: PQW1074 | E8: E0172震动 | H8: 4-20MA
B9: 7 | C9: PQW1076 | E9: E0173提升机 | H9: 4-20MA
B10: 1
B11: 5
B12: 3
B13: 7
B19: 输入
B20: 序号 | C20: 地址 | D20: 符号表 | E20: 设备编号 | F20: 设备名称 | G20: 信号名称 | H20: 设备名称（英文） | I20: 信号名称（英文） | J20: 标签 | K20: 备注 | L20: 柜号
A21: 1 | B21: 1 | C21: I236.0 | D21: =RI5-DI01 | E21: =TRIM(MID(SUBSTITUTE($J21,":",REPT(" ",40)),1,40)) -> E0153_1 | F21: =TRIM(MID(SUBSTITUTE($J21,":",REPT(" ",40)),40,40)) -> 喷涂机 | G21: =TRIM(MID(SUBSTITUTE($J21,":",REPT(" ",40)),80,40)) -> 运行 | H21: =TRIM(MID(SUBSTITUTE($J21,":",H23+REPT(" ",40)),120,40)) -> #VALUE! | I21: =TRIM(MID(SUBSTITUTE($J21,":",REPT(" ",40)),160,40)) -> Running | J21: E0153_1:喷涂机:运行:Coater:Running | M21: ¶ | N21: - | O21: =D21 -> =RI5-DI01 | P21: =A21 -> 1 | Q21: =C21 -> I236.0 | R21: =E21&M21&F21&G21&M21&H21&I21 -> #VALUE!
A22: 2 | B22: 2 | C22: I236.1 | D22: =RI5-DI01 | E22: =TRIM(MID(SUBSTITUTE($J22,":",REPT(" ",40)),1,40)) -> E0153_2 | F22: =TRIM(MID(SUBSTITUTE($J22,":",REPT(" ",40)),40,40)) -> 喷涂机 | G22: =TRIM(MID(SUBSTITUTE($J22,":",REPT(" ",40)),80,40)) -> 运行 | H22: =TRIM(MID(SUBSTITUTE($J22,":",REPT(" ",40)),120,40)) -> Coater | I22: =TRIM(MID(SUBSTITUTE($J22,":",REPT(" ",40)),160,40)) -> Running | J22: E0153_2:喷涂机:运行:Coater:Running | M22: ¶ | N22: - | O22: =D22 -> =RI5-DI01 | P22: =A22 -> 2 | Q22: =C22 -> I236.1 | R22: =E22&M22&F22&G22&M22&H22&I22 -> E0153_2¶喷涂机运行¶CoaterRunning
A23: 3 | B23: 3 | C23: I236.2 | D23: =RI5-DI01 | E23: =TRIM(MID(SUBSTITUTE($J23,":",REPT(" ",40)),1,40)) -> E0153 | F23: =TRIM(MID(SUBSTITUTE($J23,":",REPT(" ",40)),40,40)) -> 喷涂机 | G23: =TRIM(MID(SUBSTITUTE($J23,":",REPT(" ",40)),80,40)) -> 门保 | H23: =TRIM(MID(SUBSTITUTE($J23,":",REPT(" ",40)),120,40)) -> Coater | I23: =TRIM(MID(SUBSTITUTE($J23,":",REPT(" ",40)),160,40)) -> Door Protect | J23: E0153:喷涂机:门保:Coater:Door Protect | M23: ¶ | N23: - | O23: =D23 -> =RI5-DI01 | P23: =A23 -> 3 | Q23: =C23 -> I236.2 | R23: =E23&M23&F23&G23&M23&H23&I23 -> E0153¶喷涂机门保¶CoaterDoor Protect
A24: 4 | B24: 4 | C24: I236.3 | D24: =RI5-DI01 | E24: =TRIM(MID(SUBSTITUTE($J24,":",REPT(" ",40)),1,40)) -> E0153V0- | F24: =TRIM(MID(SUBSTITUTE($J24,":",REPT(" ",40)),40,40)) -> 出料门 | G24: =TRIM(MID(SUBSTITUTE($J24,":",REPT(" ",40)),80,40)) -> 开门到位 | H24: =TRIM(MID(SUBSTITUTE($J24,":",REPT(" ",40)),120,40)) -> Valve | I24: =TRIM(MID(SUBSTITUTE($J24,":",REPT(" ",40)),160,40)) -> Openning | J24: E0153V0-:出料门:开门到位:Valve:Openning | M24: ¶ | N24: - | O24: =D24 -> =RI5-DI01 | P24: =A24 -> 4 | Q24: =C24 -> I236.3 | R24: =E24&M24&F24&G24&M24&H24&I24 -> E0153V0-¶出料门开门到位¶ValveOpenning
A25: 5 | B25: 5 | C25: I236.4 | D25: =RI5-DI01 | E25: =TRIM(MID(SUBSTITUTE($J25,":",REPT(" ",40)),1,40)) -> E0153V0- | F25: =TRIM(MID(SUBSTITUTE($J25,":",REPT(" ",40)),40,40)) -> 出料门 | G25: =TRIM(MID(SUBSTITUTE($J25,":",REPT(" ",40)),80,40)) -> 关门到位 | H25: =TRIM(MID(SUBSTITUTE($J25,":",REPT(" ",40)),120,40)) -> Valve | I25: =TRIM(MID(SUBSTITUTE($J25,":",REPT(" ",40)),160,40)) -> Closing | J25: E0153V0-:出料门:关门到位:Valve:Closing | M25: ¶ | N25: - | O25: =D25 -> =RI5-DI01 | P25: =A25 -> 5 | Q25: =C25 -> I236.4 | R25: =E25&M25&F25&G25&M25&H25&I25 -> E0153V0-¶出料门关门到位¶ValveClosing
